Workbook

Sheet 표지
A1: 타워크레인공사 발주의뢰서
A4: 결 재 | B4: 작 성 | C4: 검 토 | E4: 승 인 | H4: 결 재 | I4: 접 수 | J4: 검 토 | L4: 승 인
A12: 2023년 12월 일
G15: 발 송 일 자 | J15: 2023년 12월 일
G16: 계 약 기 한 | J16: 2023년 12월 일
G17: 공사투입예정일 | J17: 2023년 12월 일
A20: 이천중리2차 공동주택 신축공사

Sheet 내역서
A1: [이천중리2차] 타워크레인 내역서
A3: 명 칭 | B3: 규 격 | C3: 단위 | D3: 수량 | E3: 재료비 | G3: 노무비 | I3: 경 비 | K3: 합 계 | M3: 비 고
E4: 단가 | F4: 금액 | G4: 단가 | H4: 금액 | I4: 단가 | J4: 금액 | K4: 단가 | L4: 금액
A5: 1. 임대료
A6: =산출서!B5 -> 타워크레인 (1호기) | B6: ='발주수량 검토'!C7 -> L형/18T/60M/END 2.14T | C6: =산출서!D5 -> 월 | D6: ='발주수량 검토'!I7 -> 12 | F6: =D6*E6 -> 0 | H6: =D6*G6 -> 0 | J6: =D6*I6 -> 0 | K6: =E6+G6+I6 -> 0 | L6: =F6+H6+J6 -> 0
A7: =산출서!B6 -> 타워크레인 (2호기) | B7: ='발주수량 검토'!C8 -> L형/18T/50M/END 3.25T | C7: =산출서!D6 -> 월 | D7: ='발주수량 검토'!I8 -> 13 | F7: =D7*E7 -> 0 | H7: =D7*G7 -> 0 | J7: =D7*I7 -> 0 | K7: =E7+G7+I7 -> 0 | L7: =F7+H7+J7 -> 0
A8: =산출서!B7 -> 타워크레인 (3호기) | B8: ='발주수량 검토'!C9 -> L형/18T/60M/END 2.14T | C8: =산출서!D7 -> 월 | D8: ='발주수량 검토'!I9 -> 13 | F8: =D8*E8 -> 0 | H8: =D8*G8 -> 0 | J8: =D8*I8 -> 0 | K8: =E8+G8+I8 -> 0 | L8: =F8+H8+J8 -> 0
A9: =산출서!B8 -> 타워크레인 (4호기) | B9: ='발주수량 검토'!C10 -> T형/12T/70M/END 3.2T | C9: =산출서!D8 -> 월 | D9: ='발주수량 검토'!I10 -> 13 | F9: =D9*E9 -> 0 | H9: =D9*G9 -> 0 | J9: =D9*I9 -> 0 | K9: =E9+G9+I9 -> 0 | L9: =F9+H9+J9 -> 0
A10: =산출서!B9 -> 타워크레인 (5호기) | B10: ='발주수량 검토'!C11 -> L형/18T/60M/END 2.14T | C10: =산출서!D9 -> 월 | D10: ='발주수량 검토'!I11 -> 12 | F10: =D10*E10 -> 0 | H10: =D10*G10 -> 0 | J10: =D10*I10 -> 0 | K10: =E10+G10+I10 -> 0 | L10: =F10+H10+J10 -> 0
A11: =산출서!B10 -> 타워크레인 (6호기) | B11: ='발주수량 검토'!C12 -> T형/12T/70M/END 3.2T | C11: =산출서!D10 -> 월 | D11: ='발주수량 검토'!I12 -> 13 | F11: =D11*E11 -> 0 | H11: =D11*G11 -> 0 | J11: =D11*I11 -> 0 | K11: =E11+G11+I11 -> 0 | L11: =F11+H11+J11 -> 0
A12: =산출서!B12 -> 추가마스터 임대료 | C12: =산출서!D12 -> 개당월 | D12: ='발주수량 검토'!I13 -> 280 | F12: =D12*E12 -> 0 | H12: =D12*G12 -> 0 | J12: =D12*I12 -> 0 | K12: =E12+G12+I12 -> 0 | L12: =F12+H12+J12 -> 0
A13: 계 | F13: =SUM(F6:F12) -> 0 | H13: =SUM(H6:H12) -> 0 | J13: =SUM(J6:J12) -> 0 | L13: =SUM(L6:L12) -> 0
A14: 2. 공사비
A15: 기초앙카비 | B15: 설치비 포함 | C15: 조 | D15: ='발주수량 검토'!I15 -> 6 | F15: =D15*E15 -> 0 | H15: =D15*G15 -> 0 | J15: =D15*I15 -> 0 | K15: =F15+H15+J15 -> 0 | L15: =F15+H15+J15 -> 0
A16: 인상작업비(텔레스코핑) | C16: 회 | D16: ='발주수량 검토'!I16 -> 16 | F16: =D16*E16 -> 0 | H16: =D16*G16 -> 0 | J16: =D16*I16 -> 0 | K16: =F16+H16+J16 -> 0 | L16: =F16+H16+J16 -> 0
A17: 브레싱작업비 | B17: 전체.EMBED 설치.자재 포함 | C17: 회 | D17: ='발주수량 검토'!I17 -> 16 | F17: =D17*E17 -> 0 | H17: =D17*G17 -> 0 | J17: =D17*I17 -> 0 | K17: =F17+H17+J17 -> 0 | L17: =F17+H17+J17 -> 0
A18: 브레싱자재비 | C18: 회 | D18: ='발주수량 검토'!I18 -> 16 | F18: =D18*E18 -> 0 | H18: =D18*G18 -> 0 | J18: =D18*I18 -> 0 | K18: =F18+H18+J18 -> 0 | L18: =F18+H18+J18 -> 0
A19: 설치공사비 | C19: 회 | D19: ='발주수량 검토'!I19 -> 6 | F19: =D19*E19 -> 0 | H19: =D19*G19 -> 0 | J19: =D19*I19 -> 0 | K19: =F19+H19+J19 -> 0 | L19: =F19+H19+J19 -> 0
A20: 해체공사비 | C20: 회 | D20: ='발주수량 검토'!I20 -> 6 | F20: =D20*E20 -> 0 | H20: =D20*G20 -> 0 | J20: =D20*I20 -> 0 | K20: =F20+H20+J20 -> 0 | L20: =F20+H20+J20 -> 0
A21: 운반비/편도 | B21: 편도 | C21: 회 | D21: ='발주수량 검토'!I21 -> 6 | F21: =D21*E21 -> 0 | H21: =D21*G21 -> 0 | J21: =D21*I21 -> 0 | K21: =F21+H21+J21 -> 0 | L21: =F21+H21+J21 -> 0
A22: 추가마스타운반비 | B22: 왕복 | C22: 개 | D22: ='발주수량 검토'!I22 -> 280 | F22: =D22*E22 -> 0 | H22: =D22*G22 -> 0 | J22: =D22*I22 -> 0 | K22: =F22+H22+J22 -> 0 | L22: =F22+H22+J22 -> 0
A23: 비파괴검사 | B23: 자립고, 추가마스터, 부품 등 | C23: 조 | D23: ='발주수량 검토'!I23 -> 6 | F23: =D23*E23 -> 0 | H23: =D23*G23 -> 0 | J23: =D23*I23 -> 0 | K23: =F23+H23+J23 -> 0 | L23: =F23+H23+J23 -> 0 | M23: (자분+초음파) 추가마스터 포함
A24: T/C방호 울타리 | B24: 완성검사시 필요물량 | C24: 조 | D24: ='발주수량 검토'!I24 -> 6 | F24: =D24*E24 -> 0 | H24: =D24*G24 -> 0 | J24: =D24*I24 -> 0 | K24: =F24+H24+J24 -> 0 | L24: =F24+H24+J24 -> 0
A25: 야간 작업등 | B25: 설치비 포함 | C25: 조 | D25: ='발주수량 검토'!I25 -> 6 | F25: =D25*E25 -> 0 | H25: =D25*G25 -> 0 | J25: =D25*I25 -> 0 | K25: =F25+H25+J25 -> 0 | L25: =F25+H25+J25 -> 0 | M25: 메인판넬 분전함 , 변압기 안전망 포함
A26: 풍속계 | B26: 무선방식 타워= 사무실 설치 | C26: 조 | D26: ='발주수량 검토'!I26 -> 1 | F26: =D26*E26 -> 0 | H26: =D26*G26 -> 0 | J26: =D26*I26 -> 0 | K26: =F26+H26+J26 -> 0 | L26: =F26+H26+J26 -> 0
A27: 브래싱 구조검토비 | B27: 설치비 포함 | C27: 조 | D27: ='발주수량 검토'!I27 -> 6 | F27: =D27*E27 -> 0 | H27: =D27*G27 -> 0 | J27: =D27*I27 -> 0 | K27: =F27+H27+J27 -> 0 | L27: =F27+H27+J27 -> 0
A28: 항공장애등 | B28: 중광도A | C28: 대 | D28: ='발주수량 검토'!I28 -> 6 | F28: =D28*E28 -> 0 | H28: =D28*G28 -> 0 | J28: =D28*I28 -> 0 | K28: =F28+H28+J28 -> 0 | L28: =F28+H28+J28 -> 0
A29: 타워크레인 건널다리 | C29: EA | D29: ='발주수량 검토'!I29 -> 6 | F29: =D29*E29 -> 0 | H29: =D29*G29 -> 0 | J29: =D29*I29 -> 0 | K29: =F29+H29+J29 -> 0 | L29: =F29+H29+J29 -> 0
A30: 계 | F30: =SUM(F15:F28) -> 0 | H30: =SUM(H15:H28) -> 0 | J30: =SUM(J15:J28) -> 0 | L30: =F30+H30+J30 -> 0
A31: 3. 초과근무수당
A32: 1호기 | B32: (평일:1시간,토요일:7시간) | C32: 개월 | D32: ='발주수량 검토'!I31 -> 12 | F32: =D32*E32 -> 0 | H32: =D32*G32 -> 0 | J32: =D32*I32 -> 0 | K32: =E32+G32+I32 -> 0 | L32: =F32+H32+J32 -> 0
A33: 2호기 | B33: (평일:1시간,토요일:7시간) | C33: 개월 | D33: ='발주수량 검토'!I32 -> 13 | F33: =D33*E33 -> 0 | H33: =D33*G33 -> 0 | J33: =D33*I33 -> 0 | K33: =E33+G33+I33 -> 0 | L33: =F33+H33+J33 -> 0
A34: 3호기 | B34: (평일:1시간,토요일:7시간) | C34: 개월 | D34: ='발주수량 검토'!I33 -> 13 | F34: =D34*E34 -> 0 | H34: =D34*G34 -> 0 | J34: =D34*I34 -> 0 | K34: =E34+G34+I34 -> 0 | L34: =F34+H34+J34 -> 0
A35: 4호기 | B35: (평일:1시간,토요일:7시간) | C35: 개월 | D35: ='발주수량 검토'!I34 -> 13 | F35: =D35*E35 -> 0 | H35: =D35*G35 -> 0 | J35: =D35*I35 -> 0 | K35: =E35+G35+I35 -> 0 | L35: =F35+H35+J35 -> 0
A36: 5호기 | B36: (평일:1시간,토요일:7시간) | C36: 개월 | D36: ='발주수량 검토'!I35 -> 12 | F36: =D36*E36 -> 0 | H36: =D36*G36 -> 0 | J36: =D36*I36 -> 0 | K36: =E36+G36+I36 -> 0 | L36: =F36+H36+J36 -> 0
A37: 6호기 | B37: (평일:1시간,토요일:7시간) | C37: 개월 | D37: ='발주수량 검토'!I36 -> 13 | F37: =D37*E37 -> 0 | H37: =D37*G37 -> 0 | J37: =D37*I37 -> 0 | K37: =E37+G37+I37 -> 0 | L37: =F37+H37+J37 -> 0
A38: 계 | F38: =SUM(F32:F37) -> 0 | H38: =SUM(H32:H37) -> 0 | J38: =SUM(J32:J37) -> 0 | L38: =SUM(L32:L37) -> 0
A39: 소 계 (1+2+3) | F39: =F13+F30+F38 -> 0 | H39: =H13+H30+H38 -> 0 | J39: =J13+J30+J38 -> 0 | L39: =L13+L30+L38 -> 0
A40: 4. 보험료 기타
A41: 설,해체 작업 | B41: 3억기준 | C41: 회 | D41: 12 | F41: =D41*E41 -> 0 | H41: =D41*G41 -> 0 | J41: =D41*I41 -> 0 | K41: =E41+G41+I41 -> 0 | L41: =F41+H41+J41 -> 0
...

Sheet 산출서
B1: 타워크레인 임대 현황
B2: 현장명 : 이천중리2차
B3: 명 칭 | C3: 규 격 | D3: 단위 | E3: 호기 | F3: 당초계획 | H3: 2023년 | T3: 2024년 | AF3: 2025년 | AG3: 합 계 | AH3: 비고
H4: 1월 | I4: 2월 | J4: 3월 | K4: 4월 | L4: 5월 | M4: 6월 | N4: 7월 | O4: 8월 | P4: 9월 | Q4: 10월 | R4: 11월 | S4: 12월 | T4: 1월 | U4: 2월 | V4: 3월 | W4: 4월 | X4: 5월 | Y4: 6월 | Z4: 7월 | AA4: 8월 | AB4: 9월 | AC4: 10월 | AD4: 11월 | AE4: 12월 | AF4: 1월
B5: 타워크레인 (1호기) | C5: L형/18T/60M/END 2.14T | D5: 월 | E5: 1호기 | F5: '24. 02 ~ '25.02 | I5: 1 | J5: 1 | K5: 1 | L5: 1 | M5: 1 | N5: 1 | O5: 1 | P5: 1 | Q5: 1 | R5: 1 | S5: 1 | T5: 1 | U5: 1 | AG5: =SUM(H5:AF5) -> 13
B6: 타워크레인 (2호기) | C6: L형/18T/50M/END 3.25T | D6: 월 | E6: 2호기 | F6: '24. 03 ~ '25.03 | J6: 1 | K6: 1 | L6: 1 | M6: 1 | N6: 1 | O6: 1 | P6: 1 | Q6: 1 | R6: 1 | S6: 1 | T6: 1 | U6: 1 | V6: 1 | AG6: =SUM(H6:AF6) -> 13
B7: 타워크레인 (3호기) | C7: L형/18T/60M/END 2.14T | D7: 월 | E7: 3호기 | F7: '24. 04 ~ '25.04 | K7: 1 | L7: 1 | M7: 1 | N7: 1 | O7: 1 | P7: 1 | Q7: 1 | R7: 1 | S7: 1 | T7: 1 | U7: 1 | V7: 1 | W7: 1 | AG7: =SUM(H7:AE7) -> 13
B8: 타워크레인 (4호기) | C8: T형/12T/70M/END 3.2T | D8: 월 | E8: 4호기 | F8: '24. 04 ~ '25.04 | K8: 1 | L8: 1 | M8: 1 | N8: 1 | O8: 1 | P8: 1 | Q8: 1 | R8: 1 | S8: 1 | T8: 1 | U8: 1 | V8: 1 | W8: 1 | AG8: =SUM(H8:AE8) -> 13
B9: 타워크레인 (5호기) | C9: L형/18T/60M/END 2.14T | D9: 월 | E9: 5호기 | F9: '24. 02 ~ '25.02 | I9: 1 | J9: 1 | K9: 1 | L9: 1 | M9: 1 | N9: 1 | O9: 1 | P9: 1 | Q9: 1 | R9: 1 | S9: 1 | T9: 1 | U9: 1 | AG9: =SUM(H9:AE9) -> 13
B10: 타워크레인 (6호기) | C10: T형/12T/70M/END 3.2T | D10: 월 | E10: 6호기 | F10: '24. 03 ~ '25.04 | J10: 1 | K10: 1 | L10: 1 | M10: 1 | N10: 1 | O10: 1 | P10: 1 | Q10: 1 | R10: 1 | S10: 1 | T10: 1 | U10: 1 | V10: 1 | W10: 1 | AG10: =SUM(H10:AE10) -> 14
E11: 계 | AG11: =SUM(AG5:AG10) -> 79
B12: 추가마스터 임대료 | D12: 개당월 | E12: 1호기 | F12: 기본(8EA) | AH12: 추가마스터:8EA
F13: 1차(4EA) | G13: 브레싱: 101동 10층 | Q13: 4 | R13: 4 | S13: 4 | T13: 4 | U13: 4 | AG13: =SUM(H13:AF13) -> 20
F14: 2차(4EA) | G14: 브레싱: 101동 13층 | R14: 4 | S14: 4 | T14: 4 | U14: 4 | AG14: =SUM(H14:AF14) -> 16
D15: 15 | F15: 27 | G15: 소계 | H15: =SUM(H12:H14) -> 0 | I15: =SUM(I12:I14) -> 0 | J15: =SUM(J12:J14) -> 0 | K15: =SUM(K12:K14) -> 0 | L15: =SUM(L12:L14) -> 0 | M15: =SUM(M12:M14) -> 0 | N15: =SUM(N12:N14) -> 0 | O15: =SUM(O12:O14) -> 0 | ... AE15: =SUM(AE12:AE14) -> 0 | AG15: =SUM(H15:AE15) -> 36
E16: 2호기 | F16: 기본(8EA) | AH16: 추가마스터:12EA
F17: 1차(4EA) | G17: 브레싱: 103동 8층 | Q17: 4 | R17: 4 | S17: 4 | T17: 4 | U17: 4 | V17: 4 | AG17: =SUM(H17:AF17) -> 24
F18: 2차(4EA) | G18: 브레싱: 103동 12층 | S18: 4 | T18: 4 | U18: 4 | V18: 4 | AG18: =SUM(H18:AF18) -> 16
F19: 3차(4EA) | G19: 브레싱:103동 16층 | T19: 4 | U19: 4 | V19: 4 | AG19: =SUM(H19:AF19) -> 12
D20: 15 | F20: 23 | G20: 소계 | H20: =SUM(H16:H19) -> 0 | I20: =SUM(I16:I19) -> 0 | J20: =SUM(J16:J19) -> 0 | K20: =SUM(K16:K19) -> 0 | L20: =SUM(L16:L19) -> 0 | M20: =SUM(M16:M19) -> 0 | N20: =SUM(N16:N19) -> 0 | O20: =SUM(O16:O19) -> 0 | ... AE20: =SUM(AE16:AE19) -> 0 | AG20: =SUM(H20:AE20) -> 52
E21: 3호기 | F21: 기본(7EA) | AH21: 추가마스터:9EA
F22: 1차(3EA) | G22: 브레싱: 104동 6층 | Q22: 3 | R22: 3 | S22: 3 | T22: 3 | U22: 3 | V22: 3 | W22: 3 | AG22: =SUM(H22:AE22) -> 21
F23: 2차(3EA) | G23: 브레싱: 104동 10층 | S23: 3 | T23: 3 | U23: 3 | V23: 3 | W23: 3 | AG23: =SUM(H23:AE23) -> 15
F24: 3차(3EA) | G24: 브레싱: 104동 14층 | T24: 3 | U24: 3 | V24: 3 | W24: 3 | AG24: =SUM(H24:AE24) -> 12
D25: 9 | F25: 16 | G25: 소계 | H25: =SUM(H21:H24) -> 0 | I25: =SUM(I21:I24) -> 0 | J25: =SUM(J21:J24) -> 0 | K25: =SUM(K21:K24) -> 0 | L25: =SUM(L21:L24) -> 0 | M25: =SUM(M21:M24) -> 0 | N25: =SUM(N21:N24) -> 0 | O25: =SUM(O21:O24) -> 0 | ... AE25: =SUM(AE21:AE24) -> 0 | AG25: =SUM(H25:AE25) -> 48
E26: 4호기 | F26: 기본(7EA) | AH26: 추가마스터:13EA
F27: 1차(3EA) | G27: 브레싱: 106동 8층 | R27: 5 | S27: 5 | T27: 5 | U27: 5 | V27: 5 | W27: 5 | AG27: =SUM(H27:AE27) -> 30
F28: 2차(3EA) | G28: 브레싱: 106동 13층 | T28: 4 | U28: 4 | V28: 4 | W28: 4 | AG28: =SUM(H28:AE28) -> 16
F29: 3차(3EA) | G29: 브레싱: 106동 19층 | V29: 4 | W29: 4 | AG29: =SUM(H29:AE29) -> 8
D30: 9 | F30: 16 | G30: 소계 | H30: =SUM(H26:H29) -> 0 | I30: =SUM(I26:I29) -> 0 | J30: =SUM(J26:J29) -> 0 | K30: =SUM(K26:K29) -> 0 | L30: =SUM(L26:L29) -> 0 | M30: =SUM(M26:M29) -> 0 | N30: =SUM(N26:N29) -> 0 | O30: =SUM(O26:O29) -> 0 | ... AE30: =SUM(AE26:AE29) -> 0 | AG30: =SUM(H30:AE30) -> 54
E31: 5호기 | F31: 기본(8EA) | AH31: 추가마스터:10EA
F32: 1차(4EA) | G32: 브레싱: 108동 10층 | Q32: 5 | R32: 5 | S32: 5 | T32: 5 | U32: 5 | AG32: =SUM(H32:AE32) -> 25
F33: 2차(4EA) | G33: 브레싱: 108동 16층 | S33: 5 | T33: 5 | U33: 5 | AG33: =SUM(H33:AE33) -> 15
D34: 12 | F34: 24 | G34: 소계 | H34: =SUM(H31:H33) -> 0 | I34: =SUM(I31:I33) -> 0 | J34: =SUM(J31:J33) -> 0 | K34: =SUM(K31:K33) -> 0 | L34: =SUM(L31:L33) -> 0 | M34: =SUM(M31:M33) -> 0 | N34: =SUM(N31:N33) -> 0 | O34: =SUM(O31:O33) -> 0 | ... AE34: =SUM(AE31:AE33) -> 0 | AG34: =SUM(H34:AE34) -> 40
E35: 6호기 | F35: 기본(10EA) | AH35: 추가마스터:10EA
F36: 1차(5EA) | G36: 브레싱: 110동 10층 | R36: 5 | S36: 5 | T36: 5 | U36: 5 | V36: 5 | W36: 5 | AG36: =SUM(H36:AE36) -> 30
F37: 2차(5EA) | G37: 브레싱: 110동 15층 | T37: 5 | U37: 5 | V37: 5 | W37: 5 | AG37: =SUM(H37:AE37) -> 20
D38: 15 | F38: 25 | G38: 소계 | H38: =SUM(H35:H37) -> 0 | I38: =SUM(I35:I37) -> 0 | J38: =SUM(J35:J37) -> 0 | K38: =SUM(K35:K37) -> 0 | L38: =SUM(L35:L37) -> 0 | M38: =SUM(M35:M37) -> 0 | N38: =SUM(N35:N37) -> 0 | O38: =SUM(O35:O37) -> 0 | ... AE38: =SUM(AE35:AE37) -> 0 | AG38: =SUM(H38:AE38) -> 50
E39: 계 | H39: =H15+H20+H25+H30+H34+H38 -> 0 | I39: =I15+I20+I25+I30+I34+I38 -> 0 | J39: =J15+J20+J25+J30+J34+J38 -> 0 | K39: =K15+K20+K25+K30+K34+K38 -> 0 | L39: =L15+L20+L25+L30+L34+L38 -> 0 | M39: =M15+M20+M25+M30+M34+M38 -> 0 | N39: =N15+N20+N25+N30+N34+N38 -> 0 | O39: =O15+O20+O25+O30+O34+O38 -> 0 | ... AE39: =AE15+AE20+AE25+AE30+AE34+AE38 -> 0 | AG39: =AG15+AG20+AG25+AG30+AG34+AG38 -> 280

Sheet 발주수량 검토
A1: 발주수량 검토
B2: [이천중리2차]
B3: 품 명 | C3: 규 격 | D3: 단 위 | E3: 가실행 수량 (건축예산팀) | F3: 품 명 | G3: 규 격 | H3: 단 위 | I3: 발주수량 | J3: 증김 | L3: 사 유
J4: 수량 | K4: 비율
B5: 타워크레인공사 | F5: 타워크레인공사
B6: 1. 임대료 | F6: 1. 임대료
B7: 타워크레인 (1호기) | C7: L형/18T/60M/END 2.14T | D7: 월 | E7: =임대기간!J11 -> 12 | F7: 타워크레인 (1호기) | G7: L형/18T/60M/END 2.14T | H7: 월 | I7: =E7 -> 12 | J7: =E7-I7 -> 0 | K7: =IFERROR(J7/I7,0) -> 0
B8: 타워크레인 (2호기) | C8: L형/18T/50M/END 3.25T | D8: 월 | E8: =임대기간!J13 -> 13 | F8: 타워크레인 (2호기) | G8: L형/18T/50M/END 3.25T | H8: 월 | I8: =E8 -> 13 | J8: =E8-I8 -> 0 | K8: =IFERROR(J8/I8,0) -> 0
B9: 타워크레인 (3호기) | C9: L형/18T/60M/END 2.14T | D9: 월 | E9: =임대기간!J14 -> 13 | F9: 타워크레인 (3호기) | G9: L형/18T/60M/END 2.14T | H9: 월 | I9: =E9 -> 13 | J9: =E9-I9 -> 0 | K9: =IFERROR(J9/I9,0) -> 0
B10: 타워크레인 (4호기) | C10: T형/12T/70M/END 3.2T | D10: 월 | E10: =임대기간!J16 -> 13 | F10: 타워크레인 (4호기) | G10: T형/12T/70M/END 3.2T | H10: 월 | I10: =E10 -> 13 | J10: =E10-I10 -> 0 | K10: =IFERROR(J10/I10,0) -> 0
B11: 타워크레인 (5호기) | C11: L형/18T/60M/END 2.14T | D11: 월 | E11: =임대기간!J19 -> 12 | F11: 타워크레인 (5호기) | G11: L형/18T/60M/END 2.14T | H11: 월 | I11: =E11 -> 12 | J11: =E11-I11 -> 0 | K11: =IFERROR(J11/I11,0) -> 0
B12: 타워크레인 (6호기) | C12: T형/12T/70M/END 3.2T | D12: 월 | E12: =임대기간!J21 -> 13 | F12: 타워크레인 (6호기) | G12: T형/12T/70M/END 3.2T | H12: 월 | I12: =E12 -> 13 | J12: =E12-I12 -> 0 | K12: =IFERROR(J12/I12,0) -> 0
B13: 추가마스터 임대료 | D13: 개당월 | E13: 280 | F13: 추가마스터 임대료 | H13: 개당월 | I13: =산출서!AG39 -> 280 | J13: =E13-I13 -> 0 | K13: =IFERROR(J13/I13,0) -> 0
B14: 2. 공사비 | F14: 2. 공사비 | J14: =E14-I14 -> 0 | K14: =IFERROR(J14/I14,0) -> 0
B15: 기초앙카비 | C15: 설치비 포함 | D15: 조 | E15: 6 | F15: 기초앙카비 | G15: 설치비 포함 | H15: 조 | I15: 6 | J15: =E15-I15 -> 0 | K15: =IFERROR(J15/I15,0) -> 0
B16: 인상작업비(텔레스코핑) | D16: 회 | E16: 16 | F16: 인상작업비(텔레스코핑) | H16: 회 | I16: 16 | J16: =E16-I16 -> 0 | K16: =IFERROR(J16/I16,0) -> 0
B17: 브레싱작업비 | C17: 전체.EMBED 설치.자재 포함 | D17: 회 | E17: 16 | F17: 브레싱작업비 | G17: 전체.EMBED 설치.자재 포함 | H17: 회 | I17: 16 | J17: =E17-I17 -> 0 | K17: =IFERROR(J17/I17,0) -> 0
B18: 브레싱자재비 | D18: 회 | E18: 16 | F18: 브레싱자재비 | H18: 회 | I18: 16 | J18: =E18-I18 -> 0 | K18: =IFERROR(J18/I18,0) -> 0
B19: 설치공사비 | D19: 회 | E19: 6 | F19: 설치공사비 | H19: 회 | I19: 6 | J19: =E19-I19 -> 0 | K19: =IFERROR(J19/I19,0) -> 0
B20: 해체공사비 | D20: 회 | E20: 6 | F20: 해체공사비 | H20: 회 | I20: 6 | J20: =E20-I20 -> 0 | K20: =IFERROR(J20/I20,0) -> 0
B21: 운반비/편도 | C21: 편도 | D21: 회 | E21: 6 | F21: 운반비/편도 | G21: 편도 | H21: 회 | I21: 6 | J21: =E21-I21 -> 0 | K21: =IFERROR(J21/I21,0) -> 0
B22: 추가마스타운반비 | C22: 왕복 | D22: 개 | E22: =산출서!AG39 -> 280 | F22: 추가마스타운반비 | G22: 왕복 | H22: 개 | I22: =산출서!AG39 -> 280 | J22: =E22-I22 -> 0 | K22: =IFERROR(J22/I22,0) -> 0
B23: 비파괴검사 | C23: 자립고, 추가마스터, 부품 등 | D23: 조 | E23: 6 | F23: 비파괴검사 | G23: 자립고, 추가마스터, 부품 등 | H23: 조 | I23: 6 | J23: =E23-I23 -> 0 | K23: =IFERROR(J23/I23,0) -> 0
B24: T/C방호 울타리 | C24: 완성검사시 필요물량 | D24: 조 | E24: 6 | F24: T/C방호 울타리 | G24: 완성검사시 필요물량 | H24: 조 | I24: 6 | J24: =E24-I24 -> 0 | K24: =IFERROR(J24/I24,0) -> 0
B25: 야간 작업등 | C25: 설치비 포함 | D25: 조 | E25: 6 | F25: 야간 작업등 | G25: 설치비 포함 | H25: 조 | I25: 6 | J25: =E25-I25 -> 0 | K25: =IFERROR(J25/I25,0) -> 0
B26: 풍속계 | C26: 무선방식 타워= 사무실 설치 | D26: 조 | E26: 1 | F26: 풍속계 | G26: 무선방식 타워= 사무실 설치 | H26: 조 | I26: 1 | J26: =E26-I26 -> 0 | K26: =IFERROR(J26/I26,0) -> 0
B27: 브래싱 구조검토비 | C27: 설치비 포함 | D27: 조 | E27: 6 | F27: 브래싱 구조검토비 | G27: 설치비 포함 | H27: 조 | I27: 6 | J27: =E27-I27 -> 0 | K27: =IFERROR(J27/I27,0) -> 0
B28: 항공장애등 | C28: 중광도A | D28: 대 | E28: 6 | F28: 항공장애등 | G28: 중광도A | H28: 대 | I28: 6 | J28: =E28-I28 -> 0 | K28: =IFERROR(J28/I28,0) -> 0
B29: 타워크레인 건널다리 | D29: EA | E29: 6 | F29: 타워크레인 건널다리 | H29: EA | I29: 6 | J29: =E29-I29 -> 0 | K29: =IFERROR(J29/I29,0) -> 0
B30: 3. 초과근무수당 | F30: 3. 초과근무수당 | J30: =E30-I30 -> 0 | K30: =IFERROR(J30/I30,0) -> 0
B31: 1호기 | C31: (평일:1시간,토요일:7시간) | D31: 개월 | E31: =E7 -> 12 | F31: 1호기 | G31: (평일:1시간,토요일:7시간) | H31: 개월 | I31: =E31 -> 12 | J31: =E31-I31 -> 0 | K31: =IFERROR(J31/I31,0) -> 0
B32: 2호기 | C32: (평일:1시간,토요일:7시간) | D32: 개월 | E32: =E8 -> 13 | F32: 2호기 | G32: (평일:1시간,토요일:7시간) | H32: 개월 | I32: =E32 -> 13 | J32: =E32-I32 -> 0 | K32: =IFERROR(J32/I32,0) -> 0
B33: 3호기 | C33: (평일:1시간,토요일:7시간) | D33: 개월 | E33: =E9 -> 13 | F33: 3호기 | G33: (평일:1시간,토요일:7시간) | H33: 개월 | I33: =E33 -> 13 | J33: =E33-I33 -> 0 | K33: =IFERROR(J33/I33,0) -> 0
B34: 4호기 | C34: (평일:1시간,토요일:7시간) | D34: 개월 | E34: =E10 -> 13 | F34: 4호기 | G34: (평일:1시간,토요일:7시간) | H34: 개월 | I34: =E34 -> 13 | J34: =E34-I34 -> 0 | K34: =IFERROR(J34/I34,0) -> 0
B35: 5호기 | C35: (평일:1시간,토요일:7시간) | D35: 개월 | E35: =E11 -> 12 | F35: 5호기 | G35: (평일:1시간,토요일:7시간) | H35: 개월 | I35: =E35 -> 12 | J35: =E35-I35 -> 0 | K35: =IFERROR(J35/I35,0) -> 0
B36: 6호기 | C36: (평일:1시간,토요일:7시간) | D36: 개월 | E36: =E12 -> 13 | F36: 6호기 | G36: (평일:1시간,토요일:7시간) | H36: 개월 | I36: =E36 -> 13 | J36: =E36-I36 -> 0 | K36: =IFERROR(J36/I36,0) -> 0
B37: 4. 보험료 기타 | F37: 4. 보험료 기타 | J37: =E37-I37 -> 0 | K37: =IFERROR(J37/I37,0) -> 0
B38: 설,해체 작업 | C38: 3억기준 | D38: 회 | E38: 12 | F38: 설,해체 작업 | G38: 3억기준 | H38: 회 | I38: 12 | J38: =E38-I38 -> 0 | K38: =IFERROR(J38/I38,0) -> 0
B39: 인상작업보험료 | C39: 3억기준 | D39: 회 | E39: 16 | F39: 인상작업보험료 | G39: 3억기준 | H39: 회 | I39: 16 | J39: =E39-I39 -> 0 | K39: =IFERROR(J39/I39,0) -> 0
B40: 영업배상 | C40: 5억기준 | D40: 조 | E40: 6 | F40: 영업배상 | G40: 5억기준 | H40: 조 | I40: 6 | J40: =E40-I40 -> 0 | K40: =IFERROR(J40/I40,0) -> 0
...

Sheet 첨부
B1: # 첨부1
B26: # 첨부2
T54: No. | U54: 설치제원 | V54: 사용예상기간 | W54: 브레싱자재 | X54: 브레싱작업 | Y54: 인상횟수 | Z54: 추가마스트
T55: 1호기 | U55: L형/18T/60M/END 2.14T | V55: '24. 02 ~ '25.02 | W55: 2회 | X55: 2회 | Y55: 2회 | Z55: 8개
T56: 2호기 | U56: L형/14T/50M/END 3.25T | V56: '24. 03 ~ '25.03 | W56: 3회 | X56: 3회 | Y56: =X56 -> 3회 | Z56: 12게
T57: 3호기 | U57: L형/18T/60M/END 2.14T | V57: '24. 04 ~ '25.04 | W57: 3회 | X57: 3회 | Y57: =X57 -> 3회 | Z57: 9개
T58: 4호기 | U58: T형/12T/70M/END 3.2T | V58: '24. 04 ~ '25.04 | W58: 3회 | X58: 3회 | Y58: =X58 -> 3회 | Z58: 13개
T59: 5호기 | U59: L형/18T/60M/END 2.14T | V59: '24. 02 ~ '25.02 | W59: 2회 | X59: 2회 | Y59: =X59 -> 2회 | Z59: 10개
T60: 6호기 | U60: T형/12T/70M/END 3.2T | V60: '24. 03 ~ '25.04 | W60: 2회 | X60: 2회 | Y60: 3회 | Z60: 10개
W61: 총:16회 | X61: 총:16회 | Y61: 총:16회 | Z61: 총 : 62개

Sheet 작업수당
A1: [ 타워크레인 임대기간 ]
A2: 년 도 | B2: 월 | D2: 타워크레인 (1호기) | E2: 타워크레인 (2호기) | F2: 타워크레인 (3호기) | G2: 타워크레인 (4호기) | H2: 타워크레인 (5호기) | I2: 타워크레인 (6호기) | J2: 계 | K2: 비고
D3: =첨부!U55 -> L형/18T/60M/END 2.14T | E3: =첨부!U56 -> L형/14T/50M/END 3.25T | F3: =첨부!U57 -> L형/18T/60M/END 2.14T | G3: =첨부!U58 -> T형/12T/70M/END 3.2T | H3: =첨부!U59 -> L형/18T/60M/END 2.14T | I3: =첨부!U60 -> T형/12T/70M/END 3.2T
A4: 2022년 | B4: 11월 | C4: 1 | J4: =SUM(D4:I4) -> 0
B5: 12월 | C5: 2 | E5: 1 | J5: =SUM(D5:I5) -> 1
A6: 2023년 | B6: 1월 | C6: =C5+1 -> 3 | D6: 1 | E6: 1 | F6: 1 | J6: =SUM(D6:I6) -> 3
B7: 2월 | C7: =C6+1 -> 4 | D7: 1 | E7: 1 | F7: 1 | I7: 1 | J7: =SUM(D7:I7) -> 4
B8: 3월 | C8: =C7+1 -> 5 | D8: 1 | E8: 1 | F8: 1 | G8: 1 | H8: 1 | I8: 1 | J8: =SUM(D8:I8) -> 6
B9: 4월 | C9: =C8+1 -> 6 | D9: 1 | E9: 1 | F9: 1 | G9: 1 | H9: 1 | I9: 1 | J9: =SUM(D9:I9) -> 6
B10: 5월 | C10: =C9+1 -> 7 | D10: 1 | E10: 1 | F10: 1 | G10: 1 | H10: 1 | I10: 1 | J10: =SUM(D10:I10) -> 6
B11: 6월 | C11: =C10+1 -> 8 | D11: 1 | E11: 1 | F11: 1 | G11: 1 | H11: 1 | I11: 1 | J11: =SUM(D11:I11) -> 6
B12: 7월 | C12: =C11+1 -> 9 | D12: 1 | E12: 1 | F12: 1 | G12: 1 | H12: 1 | I12: 1 | J12: =SUM(D12:I12) -> 6
B13: 8월 | C13: =C12+1 -> 10 | D13: 1 | E13: 1 | F13: 1 | G13: 1 | H13: 1 | I13: 1 | J13: =SUM(D13:I13) -> 6
B14: 9월 | C14: =C13+1 -> 11 | D14: 1 | E14: 1 | F14: 1 | G14: 1 | H14: 1 | I14: 1 | J14: =SUM(D14:I14) -> 6
B15: 10월 | C15: =C14+1 -> 12 | D15: 1 | E15: 1 | F15: 1 | G15: 1 | H15: 1 | I15: 1 | J15: =SUM(D15:I15) -> 6
B16: 11월 | C16: =C15+1 -> 13 | D16: 1 | E16: 1 | F16: 1 | G16: 1 | H16: 1 | I16: 1 | J16: =SUM(D16:I16) -> 6
B17: 12월 | C17: =C16+1 -> 14 | D17: 1 | E17: 1 | F17: 1 | G17: 1 | H17: 1 | I17: 1 | J17: =SUM(D17:I17) -> 6
A18: 2024년 | B18: 1월 | C18: =C17+1 -> 15 | D18: 1 | F18: 1 | G18: 1 | H18: 1 | I18: 1 | J18: =SUM(D18:I18) -> 5
B19: 2월 | C19: =C18+1 -> 16 | D19: 1 | G19: 1 | H19: 1 | I19: 1 | J19: =SUM(D19:I19) -> 4
B20: 3월 | C20: =C19+1 -> 17 | D20: 1 | G20: 1 | H20: 1 | I20: 1 | J20: =SUM(D20:I20) -> 4
B21: 4월 | C21: =C20+1 -> 18 | D21: 1 | G21: 1 | H21: 1 | I21: 1 | J21: =SUM(D21:I21) -> 4
B22: 5월 | C22: =C21+1 -> 19 | G22: 1 | H22: 1 | I22: 1 | J22: =SUM(D22:I22) -> 3
B23: 6월 | C23: =C22+1 -> 20 | G23: 1 | H23: 1 | J23: =SUM(D23:I23) -> 2
B24: 7월 | C24: =C23+1 -> 21 | J24: =SUM(D24:I24) -> 0
B25: 8월 | C25: =C24+1 -> 22 | J25: =SUM(D25:I25) -> 0
B26: 9월 | C26: =C25+1 -> 23 | J26: =SUM(D26:I26) -> 0
B27: 10월 | C27: =C26+1 -> 24 | J27: =SUM(D27:I27) -> 0
A28: 소 계 | D28: =SUM(D4:D27) -> 16 | E28: =SUM(E4:E27) -> 13 | F28: =SUM(F4:F27) -> 13 | G28: =SUM(G4:G27) -> 16 | H28: =SUM(H4:H27) -> 16 | I28: =SUM(I4:I27) -> 16 | J28: =SUM(D28:I28) -> 90

Sheet 임대기간
A1: [ 타워크레인 임대기간 산정 ]
A2: (2023. 11. 28)
A3: ■ 현장명 :
A5: ※ 총 공기 기준 (단위:일)
A6: 지하 : | B6: 기초 - | C6: 30 | D6: 지하 - | E6: 35
A7: 지상 : | B7: 1층 - | C7: 25 | D7: 기준 - | E7: 10 | F7: 최상 - | G7: 15 | H7: 옥탑 - | I7: 15
A9: 구 분 | D9: 층 수 | H9: 골조 공기 | J9: 임대 개월(협의전) | M9: 임대 개월(협의후) | P9: 비 고
A10: 현장 | B10: 타워 | C10: 동 | D10: 지하 | E10: 지상 | F10: 1F 제외 | G10: 옥탑 | H10: 일 | I10: 월 | J10: 견적팀 | K10: 자재팀 | L10: 차이 | M10: 견적팀 | N10: 자재팀 | O10: 차이
A11: 이천중리1차 | B11: 1호기 | C11: 101동 | D11: 2 | E11: 15 | F11: 14 | G11: 2 | H11: =$C$6+$E$6*D11+$C$7+$E$7*(F11-1)+$G$7+$I$7*G11 -> 300 | I11: =ROUNDUP(MAX(H11:H12)/365*12,0) -> 11 | J11: =I11+1 -> 12 | K11: 13 | L11: =K11-J11 -> 1 | M11: =J11 -> 12 | N11: 16 | O11: =N11-M11 -> 4
C12: 102동 | D12: 2 | E12: 18 | F12: 17 | G12: 2 | H12: =$C$6+$E$6*D12+$C$7+$E$7*(F12-1)+$G$7+$I$7*G12 -> 330
B13: 2호기 | C13: 103동 | D13: 2 | E13: 20 | F13: 19 | G13: 2 | H13: =$C$6+$E$6*D13+$C$7+$E$7*(F13-1)+$G$7+$I$7*G13 -> 350 | I13: =ROUNDUP(MAX(H13:H13)/365*12,0) -> 12 | J13: =I13+1 -> 13
B14: 3호기 | C14: 104동 | D14: 2 | E14: 20 | F14: 19 | G14: 2 | H14: =$C$6+$E$6*D14+$C$7+$E$7*(F14-1)+$G$7+$I$7*G14 -> 350 | I14: =ROUNDUP(MAX(H14:H15)/365*12,0) -> 12 | J14: =I14+1 -> 13
C15: 105동 | D15: 2 | E15: 20 | F15: 19 | G15: 2 | H15: =$C$6+$E$6*D15+$C$7+$E$7*(F15-1)+$G$7+$I$7*G15 -> 350
B16: 4호기 | C16: 105 | D16: 2 | E16: 20 | F16: 19 | G16: 2 | H16: =$C$6+$E$6*D16+$C$7+$E$7*(F16-1)+$G$7+$I$7*G16 -> 350 | I16: =ROUNDUP(MAX(H16:H18)/365*12,0) -> 12 | J16: =I16+1 -> 13 | K16: 13 | L16: =K16-J16 -> 0 | M16: =J16 -> 13 | N16: 16 | O16: =N16-M16 -> 3
C17: 106 | D17: 2 | E17: 20 | F17: 19 | G17: 2 | H17: =$C$6+$E$6*D17+$C$7+$E$7*(F17-1)+$G$7+$I$7*G17 -> 350
C18: 107 | D18: 2 | E18: 17 | F18: 16 | G18: 2 | H18: =$C$6+$E$6*D18+$C$7+$E$7*(F18-1)+$G$7+$I$7*G18 -> 320
B19: 5호기 | C19: 108동 | D19: 2 | E19: 17 | F19: 16 | G19: 2 | H19: =$C$6+$E$6*D19+$C$7+$E$7*(F19-1)+$G$7+$I$7*G19 -> 320 | I19: =ROUNDUP(MAX(H19:H19)/365*12,0) -> 11 | J19: =I19+1 -> 12
C20: 109동 | D20: 2 | E20: 15 | F20: 14 | G20: 2 | H20: =$C$6+$E$6*D20+$C$7+$E$7*(F20-1)+$G$7+$I$7*G20 -> 300 | K20: 13 | L20: =K20-J20 -> 13 | M20: =J20 -> 0 | N20: 16 | O20: =N20-M20 -> 16
B21: 6호기 | C21: 110동 | D21: 2 | E21: 19 | F21: 18 | G21: 2 | H21: =$C$6+$E$6*D21+$C$7+$E$7*(F21-1)+$G$7+$I$7*G21 -> 340 | I21: =ROUNDUP(MAX(H21:H22)/365*12,0) -> 12 | J21: =I21+1 -> 13 | K21: 13 | L21: =K21-J21 -> 0 | M21: =J21 -> 13 | N21: 16 | O21: =N21-M21 -> 3
C22: 111동 | D22: 2 | E22: 20 | F22: 19 | G22: 2 | H22: =$C$6+$E$6*D22+$C$7+$E$7*(F22-1)+$G$7+$I$7*G22 -> 350
A23: 합 계 | I23: =SUM(I11:I22) -> 70 | J23: =SUM(J11:J22) -> 76 | K23: =SUM(K11:K16) -> 26 | L23: =SUM(L11:O16) -> 65 | M23: =SUM(M11:M16) -> 25 | N23: =SUM(N11:N16) -> 32 | O23: =SUM(O11:O16) -> 7
A25: ★T/C 해체시기: 골조완료+1개월(全동 동일적용)+α

Sheet 타워크레인 건널다리

Sheet 골조공사공정표
A1: 예정공정표 (골조공사)
A2: 현장명 : 이천중리1차 우미린 신축공사
A3: 구 분 | C3: 기초 | D3: B2바닥 | E3: B1바닥 | F3: B1지붕 | G3: 공 종 | H3: 근 거 | J3: 2023년 | AH3: 2024년 | DB3: 2025년 | DO3: 비 고
J4: M-30 | P4: M-29 | V4: M-28 | AB4: M-27 | AH4: M-26 | AN4: M-25 | AT4: M-24 | AZ4: M-23 | BF4: M-22 | BL4: M-21 | BR4: M-20 | BX4: M-19 | CD4: M-18 | CJ4: M-17 | CP4: M-16 | CV4: M-21 | DB4: M-20 | DH4: 25 | DI4: 26 | DJ4: 27 | DK4: 28 | DL4: 29 | DM4: 30 | DN4: 31
J5: 9월 | P5: 10월 | V5: 11월 | AB5: 12월 | AH5: 1월 | AN5: 2월 | AT5: 3월 | AZ5: 4월 | BF5: 5월 | BL5: 6월 | BR5: 7월 | BX5: 8월 | CD5: 9월 | CJ5: 10월 | CP5: 11월 | CV5: 12월 | DB5: 1월
J6: 5 | K6: 10 | L6: 15 | M6: 20 | N6: 25 | O6: 30 | P6: 5 | Q6: 10 | R6: 15 | S6: 20 | T6: 25 | U6: 30 | V6: 5 | W6: 10 | X6: 15 | Y6: 20 | Z6: 25 | AA6: 30 | AB6: 5 | AC6: 10 | AD6: 15 | AE6: 20 | AF6: 25 | AG6: 30 | AH6: 5 | AI6: 10 | AJ6: 15 | AK6: 20 | AL6: 25 | AM6: 30 | AN6: 5 | AO6: 10 | AP6: 15 | AQ6: 20 | AR6: 25 | AS6: 30 | AT6: 5 | AU6: 10 | AV6: 15 | AW6: 20 | AX6: 25 | AY6: 30 | AZ6: 5 | BA6: 10 | BB6: 15 | BC6: 20 | BD6: 25 | BE6: 30 | BF6: 5 | BG6: 10 | BH6: 15 | BI6: 20 | BJ6: 25 | BK6: 30 | BL6: 5 | BM6: 10 | BN6: 15 | BO6: 20 | BP6: 25 | BQ6: 30 | BR6: 5 | BS6: 10 | BT6: 15 | BU6: 20 | BV6: 25 | BW6: 30 | BX6: 5 | BY6: 10 | BZ6: 15 | CA6: 20 | CB6: 25 | CC6: 30 | CD6: 5 | CE6: 10 | CF6: 15 | CG6: 20 | CH6: 25 | CI6: 30 | CJ6: 5 | CK6: 10 | CL6: 15 | CM6: 20 | CN6: 25 | CO6: 30 | CP6: 5 | CQ6: 10 | CR6: 15 | CS6: 20 | CT6: 25 | CU6: 30 | CV6: 5 | CW6: 10 | CX6: 15 | CY6: 20 | CZ6: 25 | DA6: 30 | DB6: 5 | DC6: 10 | DD6: 15 | DE6: 20 | DF6: 25 | DG6: 30 | DH6: 일 | DI6: 월 | DJ6: 화 | DK6: 수 | DL6: 목 | DM6: 금 | DN6: 토
A7: 201동 | B7: 골조공사 | H7: 20F | AE7: 버림 | AG7: 기초 | AH7: 지하2층 철근 및 거푸집 | AR7: 지하1층 철근 및 거푸집 | BD7: 갱폼알폼셋팅 | BH7: 2층 | BM7: 5층 | BR7: 8층 | BW7: 11층 | CB7: 14층 | CG7: 17층 | CN7: 옥탑 및 난간작업 | DO7: 2,3호기
B9: PC공사
A11: 202동 | B11: 골조공사 | G11: 타워3호기브레싱 | H11: 19F | AB11: 버림 | AD11: 기초 | AE11: 지하2층 철근 및 거푸집 | AO11: 지하1층 철근 및 거푸집 | BA11: 갱폼알폼셋팅 | BE11: 2층 | BJ11: 5층 | BO11: 8층 | BT11: 11층 | BY11: 14층 | CD11: 17층 | CI11: 옥탑 및 난간작업 | DO11: 3호기
DP12: 5 | DQ12: 6 | DR12: 8
B13: PC공사
A15: 203동 | B15: 골조공사 | H15: 17F | Y15: 버림 | AA15: 기초 | AB15: 지하2층 철근 및 거푸집 | AL15: 지하1층 철근 및 거푸집 | AX15: 갱폼알폼셋팅 | BB15: 2층 | BG15: 5층 | BL15: 8층 | BQ15: 11층 | BV15: 14층 | CC15: 옥탑 및 난간작업 | DO15: 3호기
B17: PC공사
A19: 204동 | B19: 골조공사 | G19: 타워4호기브레싱 | H19: 17F | R19: 버림 | T19: 기초 | U19: 지하2층 철근 및 거푸집 | AE19: 지하1층 철근 및 거푸집 | AQ19: 갱폼알폼셋팅 | AU19: 2층 | AZ19: 5층 | BE19: 8층 | BJ19: 11층 | BO19: 14층 | BV19: 옥탑 및 난간작업 | DO19: 4호기
DP20: 4 | DQ20: 5 | DR20: 6
B21: PC공사 | H21: 구조물
A23: 205동 | B23: 골조공사 | H23: 19F | T23: 버림 | V23: 기초 | W23: 지하2층 철근 및 거푸집 | AG23: 지하1층 철근 및 거푸집 | AS23: 갱폼알폼셋팅 | AW23: 2층 | BB23: 5층 | BG23: 8층 | BL23: 11층 | BQ23: 14층 | BV23: 17층 | CA23: 옥탑 및 난간작업 | DO23: 4호기
B25: PC공사
A27: 206동 | B27: 골조공사 | G27: 타워5호기브레싱 | H27: 20F | W27: 버림 | Y27: 기초 | Z27: 지하2층 철근 및 거푸집 | AJ27: 지하1층 철근 및 거푸집 | AV27: 갱폼알폼셋팅 | AZ27: 2층 | BE27: 5층 | BJ27: 8층 | BO27: 11층 | BT27: 14층 | BY27: 17층 | CF27: 옥탑 및 난간작업 | DO27: 5호기
DP28: 5 | DQ28: 6 | DR28: 8
B29: PC공사 | H29: 구조물
A31: 207동 | B31: 골조공사 | H31: 20F | Z31: 버림 | AB31: 기초 | AC31: 지하2층 철근 및 거푸집 | AM31: 지하1층 철근 및 거푸집 | AY31: 갱폼알폼셋팅 | BC31: 2층 | BH31: 5층 | BM31: 8층 | BR31: 11층 | BW31: 14층 | CB31: 17층 | CI31: 옥탑 및 난간작업 | DO31: 6호기
B33: PC공사 | H33: 구조물 | DP33: 6 | DQ33: 8 | DR33: 9
A35: 208동 | B35: 골조공사 | G35: 타워6호기브레싱 | H35: 18F | AB35: 버림 | AD35: 기초 | AE35: 지하2층 철근 및 거푸집 | AO35: 지하1층 철근 및 거푸집 | BA35: 갱폼알폼셋팅 | BE35: 2층 | BJ35: 5층 | BO35: 8층 | BT35: 11층 | BY35: 14층 | CD35: 17층 | CG35: 옥탑 및 난간작업 | DO35: 6호기
B37: PC공사 | H37: 구조물
A39: 209동 | B39: 골조공사 | H39: 18F, 20F | AE39: 버림 | AG39: 기초 | AH39: 지하2층 철근 및 거푸집 | AR39: 지하1층 철근 및 거푸집 | BD39: 갱폼알폼셋팅 | BH39: 2층 | BM39: 5층 | BR39: 8층 | BW39: 11층 | CB39: 14층 | CG39: 17층 | CM39: 옥탑 및 난간작업 | DO39: 1,6호기
B41: PC공사
A43: 210동 | B43: 골조공사 | G43: 타워1호기브레싱 | H43: 20F | AJ43: 버림 | AL43: 기초 | AM43: 지하2층 철근 및 거푸집 | AW43: 지하1층 철근 및 거푸집 | BI43: 갱폼알폼셋팅 | BM43: 2층 | BR43: 5층 | BW43: 8층 | CB43: 11층 | CG43: 14층 | CL43: 17층 | CS43: 옥탑 및 난간작업 | DO43: 1호기
DP44: 8 | DQ44: 9 | DR44: 10
B45: PC공사
A47: 211동 | B47: 골조공사 | G47: 타워2호기브레싱 | H47: 20F | AI47: 버림 | AK47: 기초 | AL47: 지하2층 철근 및 거푸집 | AV47: 지하1층 철근 및 거푸집 | BH47: 갱폼알폼셋팅 | BL47: 2층 | BQ47: 5층 | BV47: 8층 | CA47: 11층 | CF47: 14층 | CK47: 17층 | CR47: 옥탑 및 난간작업 | DO47: 2호기
DP48: 7 | DQ48: 8 | DR48: 9
B49: PC공사

Sheet 골조 일정
A1: ■ 이천중리2차 우미린 골조공사 층별 일정 | AJ1: 동절기 골조공사기간 : 2024년 01월~03월 | AN1: 2024년 | AP1: 2025년
A2: 공사기간 | E2: 3 | F2: 4 | G2: 4 | H2: 9 | I2: 30 | J2: 10 | K2: 30 | L2: 10 | M2: 10 | N2: 10 | O2: 30 | P2: 20 | Q2: 15 | R2: 10 | S2: 10 | T2: 10 | U2: 10 | V2: 10 | W2: 10 | X2: 10 | Y2: 10 | Z2: 10 | AA2: 10 | AB2: 10 | AC2: 10 | AD2: 10 | AE2: 10 | AF2: 10 | AG2: 10 | AH2: 10 | AN2: 20 | AO2: 20
A3: 구분 | D3: E/V PIT | G3: 기초 | I3: B1 | K3: B2 | M3: 중층 | O3: 1F | P3: 2F | Q3: 3F | R3: 4F | S3: 5F | T3: 6F | U3: 7F | V3: 8F | W3: 9F | X3: 10F | Y3: 11F | Z3: 12F | AA3: 13F | AB3: 14F | AC3: 15F | AD3: 16F | AE3: 17F | AF3: 18F | AG3: 19F | AH3: 20F | AI3: 21F | AJ3: 22F | AK3: 23F | AL3: 24F | AM3: 25F | AN3: 옥1 | AO3: 옥2
D4: 버림 | E4: 기초 | F4: 옹벽 | G4: 버림 | H4: 기초 | I4: 옹벽 | J4: 지층 | K4: 옹벽 | L4: 지층 | M4: 옹벽 | N4: 지층
A5: 101동 (15층) | B5: B2 | D5: 44958 | E5: =+D5+E2 -> 44961 | F5: =+E5+F2 -> 44965 | G5: =+F5+G2 -> 44969 | H5: =+G5+H2 -> 44978 | I5: =+H5+I2 -> 45008 | J5: =+I5+J2 -> 45018 | K5: =J5+K2 -> 45048 | L5: =K5+L2 -> 45058 | O5: =L5+O2 -> 45088 | P5: =+O5+P2 -> 45108 | Q5: =+P5+Q2 -> 45123 | R5: =+Q5+R2 -> 45133 | S5: =+R5+S2 -> 45143 | T5: =+S5+T2 -> 45153 | U5: =+T5+U2 -> 45163 | V5: =+U5+V2 -> 45173 | W5: =+V5+W2 -> 45183 | ... AB5: =+AA5+AB2 -> 45233 | AC5: =+AB5+15 -> 45248 | AN5: =+AC5+AN2 -> 45268 | AO5: =+AN5+AO2 -> 45288 | AP5: 층변화 | AR5: 1호기 | AS5: =AO5+125 -> 45413
A6: 102동 (18층) | B6: B2 | D6: 44972 | E6: =D6+E2 -> 44975 | F6: =E6+F2 -> 44979 | G6: =F6+G2 -> 44983 | H6: =G6+H2 -> 44992 | I6: =H6+I2 -> 45022 | J6: =I6+J2 -> 45032 | K6: =J6+K2 -> 45062 | L6: =K6+L2 -> 45072 | O6: =L6+O2 -> 45102 | P6: =O6+P2 -> 45122 | Q6: =P6+Q2 -> 45137 | R6: =Q6+R2 -> 45147 | S6: =R6+S2 -> 45157 | T6: =S6+T2 -> 45167 | U6: =T6+U2 -> 45177 | V6: =U6+V2 -> 45187 | W6: =V6+W2 -> 45197 | ... AE6: =AD6+AE2 -> 45277 | AF6: =AE6+15 -> 45292 | AN6: =AF6+AN2 -> 45312 | AO6: =AN6+AO2 -> 45332 | AR6: 1호기 | AS6: =AO6+120 -> 45452
A7: 103동 (20층) | B7: B2 | D7: 44986 | E7: =+D7+E2 -> 44989 | F7: =+E7+F2 -> 44993 | G7: =+F7+G2 -> 44997 | H7: =+G7+H2 -> 45006 | I7: =+H7+I2 -> 45036 | J7: =+I7+J2 -> 45046 | K7: =+J7+K2 -> 45076 | L7: =+K7+L2 -> 45086 | O7: =L7+O2 -> 45116 | P7: =+O7+P2 -> 45136 | Q7: =+P7+Q2 -> 45151 | R7: =+Q7+R2 -> 45161 | S7: =+R7+S2 -> 45171 | T7: =+S7+T2 -> 45181 | U7: =+T7+U2 -> 45191 | V7: =+U7+V2 -> 45201 | W7: =+V7+W2 -> 45211 | ... AG7: =+AF7+AG2 -> 45311 | AH7: =+AG7+15 -> 45326 | AN7: =+AH7+AN2 -> 45346 | AO7: =+AN7+AO2 -> 45366 | AR7: 2호기 | AS7: =AO7+120 -> 45486
A8: 104동 (20층) | B8: B2 | D8: 45000 | E8: =+D8+E2 -> 45003 | F8: =+E8+F2 -> 45007 | G8: =+F8+G2 -> 45011 | H8: =+G8+H2 -> 45020 | I8: =+H8+I2 -> 45050 | J8: =+I8+J2 -> 45060 | K8: =J8+K2 -> 45090 | L8: =K8+L2 -> 45100 | O8: =L8+O2 -> 45130 | P8: =+O8+P2 -> 45150 | Q8: =+P8+Q2 -> 45165 | R8: =+Q8+R2 -> 45175 | S8: =+R8+S2 -> 45185 | T8: =+S8+T2 -> 45195 | U8: =+T8+U2 -> 45205 | V8: =+U8+V2 -> 45215 | W8: =+V8+W2 -> 45225 | ... AG8: =+AF8+AG2 -> 45325 | AH8: =+AG8+15 -> 45340 | AN8: =+AH8+AN2 -> 45360 | AO8: =+AN8+AO2 -> 45380 | AR8: 2호기 | AS8: =AO8+120 -> 45500
A9: 105동 (20층) | B9: B2 | C9: 1개층 피로티 | D9: 45017 | E9: =+D9+E2 -> 45020 | F9: =+E9+F2 -> 45024 | G9: =+F9+G2 -> 45028 | H9: =+G9+H2 -> 45037 | I9: =+H9+I2 -> 45067 | J9: =+I9+J2 -> 45077 | K9: =J9+K2 -> 45107 | L9: =K9+L2 -> 45117 | O9: =L9+O2 -> 45147 | P9: =+O9+P2 -> 45167 | Q9: =+P9+Q2 -> 45182 | R9: =+Q9+R2 -> 45192 | S9: =+R9+S2 -> 45202 | T9: =+S9+T2 -> 45212 | U9: =+T9+U2 -> 45222 | V9: =+U9+V2 -> 45232 | W9: =+V9+W2 -> 45242 | ... AG9: =+AF9+AG2 -> 45342 | AH9: =+AG9+15 -> 45357 | AN9: =+AH9+AN2 -> 45377 | AO9: =+AN9+AO2 -> 45397 | AR9: 3호기 | AS9: =AO9+120 -> 45517
A10: 106동 (20층) | B10: B2 | C10: 1개층 피로티 | D10: 45017 | E10: =+D10+E2 -> 45020 | F10: =+E10+F2 -> 45024 | G10: =+F10+G2 -> 45028 | H10: =+G10+H2 -> 45037 | I10: =+H10+I2 -> 45067 | J10: =+I10+J2 -> 45077 | K10: =J10+K2 -> 45107 | L10: =K10+L2 -> 45117 | O10: =L10+O2 -> 45147 | P10: =+O10+P2 -> 45167 | Q10: =+P10+Q2 -> 45182 | R10: =+Q10+R2 -> 45192 | S10: =+R10+S2 -> 45202 | T10: =+S10+T2 -> 45212 | U10: =+T10+U2 -> 45222 | V10: =+U10+V2 -> 45232 | W10: =+V10+W2 -> 45242 | ... AG10: =+AF10+AG2 -> 45342 | AH10: =+AG10+15 -> 45357 | AN10: =+AH10+AN2 -> 45377 | AO10: =+AN10+AO2 -> 45397 | AR10: 4호기 | AS10: =AO10+120 -> 45517
A11: 107동 (17층) | B11: B2 | D11: 45000 | E11: =+D11+E2 -> 45003 | F11: =+E11+F2 -> 45007 | G11: =+F11+G2 -> 45011 | H11: =+G11+H2 -> 45020 | I11: =+H11+I2 -> 45050 | J11: =+I11+J2 -> 45060 | K11: =+J11+K2 -> 45090 | L11: =+K11+L2 -> 45100 | O11: =L11+O2 -> 45130 | P11: =+O11+P2 -> 45150 | Q11: =+P11+Q2 -> 45165 | R11: =+Q11+R2 -> 45175 | S11: =+R11+S2 -> 45185 | T11: =+S11+T2 -> 45195 | U11: =+T11+U2 -> 45205 | V11: =+U11+V2 -> 45215 | W11: =+V11+W2 -> 45225 | ... AD11: =+AC11+AD2 -> 45295 | AE11: =+AD11+15 -> 45310 | AN11: =+AE11+AN2 -> 45330 | AO11: =+AN11+AO2 -> 45350 | AP11: 층변화 | AR11: 3,4호기 | AS11: =AO11+125 -> 45475
A12: 108동 (17층) | B12: B2 | C12: 1개층 피로티 | D12: 44972 | E12: =+D12+E2 -> 44975 | F12: =+E12+F2 -> 44979 | G12: =+F12+G2 -> 44983 | H12: =+G12+H2 -> 44992 | I12: =+H12+I2 -> 45022 | J12: =+I12+J2 -> 45032 | K12: =+J12+K2 -> 45062 | L12: =+K12+L2 -> 45072 | O12: =L12+O2 -> 45102 | P12: =+O12+P2 -> 45122 | Q12: =+P12+Q2 -> 45137 | R12: =+Q12+R2 -> 45147 | S12: =+R12+S2 -> 45157 | T12: =+S12+T2 -> 45167 | U12: =+T12+U2 -> 45177 | V12: =+U12+V2 -> 45187 | W12: =+V12+W2 -> 45197 | ... AD12: =+AC12+AD2 -> 45267 | AE12: =+AD12+15 -> 45282 | AN12: =+AE12+AN2 -> 45302 | AO12: =+AN12+AO2 -> 45322 | AR12: 5호기 | AS12: =AO12+123 -> 45445
A13: 109동 (19층) | B13: B2 | C13: 1개층 피로티 | D13: 44951 | E13: =+D13+E2 -> 44954 | F13: =+E13+F2 -> 44958 | G13: =+F13+G2 -> 44962 | H13: =+G13+H2 -> 44971 | I13: =+H13+I2 -> 45001 | J13: =+I13+J2 -> 45011 | K13: =J13+K2 -> 45041 | L13: =K13+L2 -> 45051 | O13: =L13+O2 -> 45081 | P13: =+O13+P2 -> 45101 | Q13: =+P13+Q2 -> 45116 | R13: =+Q13+R2 -> 45126 | S13: =+R13+S2 -> 45136 | T13: =+S13+T2 -> 45146 | U13: =+T13+U2 -> 45156 | V13: =+U13+V2 -> 45166 | W13: =+V13+W2 -> 45176 | ... AF13: =+AE13+AF2 -> 45266 | AG13: =+AF13+15 -> 45281 | AN13: =+AG13+AN2 -> 45301 | AO13: =+AN13+AO2 -> 45321 | AR13: 5호기 | AS13: =AO13+123 -> 45444
A14: 110동 (20층) | B14: B2 | C14: 2개층 피로티 | D14: 44986 | E14: =+D14+E2 -> 44989 | F14: =+E14+F2 -> 44993 | G14: =+F14+G2 -> 44997 | H14: =+G14+H2 -> 45006 | I14: =+H14+I2 -> 45036 | J14: =+I14+J2 -> 45046 | K14: =+J14+K2 -> 45076 | L14: =+K14+L2 -> 45086 | O14: =L14+O2 -> 45116 | P14: =+O14+P2 -> 45136 | Q14: =+P14+Q2 -> 45151 | R14: =+Q14+R2 -> 45161 | S14: =+R14+S2 -> 45171 | T14: =+S14+T2 -> 45181 | U14: =+T14+U2 -> 45191 | V14: =+U14+V2 -> 45201 | W14: =+V14+W2 -> 45211 | ... AG14: =+AF14+AG2 -> 45311 | AH14: =+AG14+15 -> 45326 | AN14: =+AH14+AN2 -> 45346 | AO14: =+AN14+AO2 -> 45366 | AR14: 6호기 | AS14: =AO14+120 -> 45486
A15: 111동 (20층) | B15: B2 | C15: 1개층 피로티 | D15: 45026 | E15: =+D15+E2 -> 45029 | F15: =+E15+F2 -> 45033 | G15: =+F15+G2 -> 45037 | H15: =+G15+H2 -> 45046 | I15: =+H15+I2 -> 45076 | J15: =+I15+J2 -> 45086 | K15: =+J15+K2 -> 45116 | L15: =+K15+L2 -> 45126 | O15: =L15+O2 -> 45156 | P15: =+O15+P2 -> 45176 | Q15: =+P15+Q2 -> 45191 | R15: =+Q15+R2 -> 45201 | S15: =+R15+S2 -> 45211 | T15: =+S15+T2 -> 45221 | U15: =+T15+U2 -> 45231 | V15: =+U15+V2 -> 45241 | W15: =+V15+W2 -> 45251 | ... AG15: =+AF15+AG2 -> 45351 | AH15: =+AG15+15 -> 45366 | AN15: =+AH15+AN2 -> 45386 | AO15: =+AN15+AO2 -> 45406 | AR15: 3,6호기 | AS15: =AO15+120 -> 45526
J19: 타워크레인 | M19: 구분 | O19: 2023년 | R19: 2024년 | AD19: 2025년
O20: 10월 | P20: 11월 | Q20: 12월 | R20: 1월 | S20: 2월 | T20: 3월 | U20: 4월 | V20: 5월 | W20: 6월 | X20: 7월 | Y20: 8월 | Z20: 9월 | AA20: 10월 | AB20: 11월 | AC20: 12월 | AD20: 1월 | AE20: 2월 | AF20: 3월 | AG20: 4월 | AH20: 5월 | AI20: 6월 | AJ20: 7월 | AK20: 8월 | AL20: 9월 | AM20: 10월 | AN20: 11월
J21: 1호기 | M21: 타 워 | N21: 1호기 | AO21: 13개월
J22: 2호기 | N22: 2호기 | AO22: 13개월
J23: 3호기 | N23: 3호기 | AO23: 13개월
J24: 4호기 | N24: 4호기 | AO24: 13개월
J25: 5호기 | N25: 5호기 | AO25: 13개월
J26: 6호기 | N26: 6호기 | AO26: 14개월
P28: 구분 | R28: 2024년 | AD28: 2025년
R29: 1월 | S29: 2월 | T29: 3월 | U29: 4월 | V29: 5월 | W29: 6월 | X29: 7월 | Y29: 8월 | Z29: 9월 | AA29: 10월 | AB29: 11월 | AC29: 12월 | AD29: 1월 | AE29: 2월 | AF29: 3월 | AG29: 4월 | AH29: 5월 | AI29: 6월 | AJ29: 7월 | AK29: 8월 | AL29: 9월 | AM29: 10월 | AN29: 11월 | AO29: 12월 | AP29: 비고
P30: 호 이 스 트 | Q30: 1동 | Y30: =S5 -> 45143 | AH30: =AS5 -> 45413 | AP30: 10개월
Q31: 2동 | Y31: =S6 -> 45157 | AI31: =AS6 -> 45452 | AP31: 11개월
Q32: 3동 | Z32: =S7 -> 45171 | AJ32: =AS7 -> 45486 | AP32: 11개월
Q33: 4동 | Z33: =S8 -> 45185 | AJ33: =AS8 -> 45500 | AP33: 11개월
Q34: 5동 | AA34: =S9 -> 45202 | AK34: =AS10 -> 45517 | AP34: 11개월
Q35: 6동 | AA35: =S10 -> 45202 | AK35: =AS10 -> 45517 | AP35: 11개월
Q36: 7동 | Z36: =S11 -> 45185 | AJ36: =AS11 -> 45475 | AP36: 11개월
Q37: 8동 | Y37: =S12 -> 45157 | AI37: =AS12 -> 45445 | AP37: 11개월
Q38: 9동 | X38: =S13 -> 45136 | AI38: =AS13 -> 45444 | AP38: 12개월
Q39: 10동 | Z39: =S14 -> 45171 | AJ39: =AS14 -> 45486 | AP39: 11개월
Q40: 11동 | AA40: =S15 -> 45211 | AK40: 45168 | AP40: 11개월
J43: 보증보험 | L43: HUG (26개월) | O43: 0.41 | P43: 1.09 | Q43: 2.3 | R43: 2.5 | S43: 3.66 | T43: 4.06 | U43: 4.06 | V43: 3.56 | W43: 3.46 | X43: 3.57 | Y43: 4.64 | Z43: 5.08 | AA43: 4.37 | AB43: 4.64 | AC43: 3.86 | AD43: 5.5 | AE43: 4.33 | AF43: 4.79 | AG43: 4.82 | AH43: 4.93 | AI43: 4.83 | AJ43: 4.8 | AK43: 5.29 | AL43: 4.34 | AM43: 2.39 | AN43: 2.74
J44: (공정율확정) | O44: =+N44+O43 -> 0.41 | P44: =+O44+P43 -> 1.5 | Q44: =+P44+Q43 -> 3.8 | R44: =+Q44+R43 -> 6.3 | S44: =+R44+S43 -> 9.96 | T44: =+S44+T43 -> 14.02 | U44: =+T44+U43 -> 18.08 | V44: =+U44+V43 -> 21.64 | ... AN44: =+AM44+AN43 -> 100.02
