Workbook

Sheet 00_개요
A1: 세대 단열재 나누기도 — 물량 검증 비교표 (초안)
A2: 스마트덱(SD) 단열 Layout 산출 결과를 실행기준·현장산출과 대조해 플랫폼 산출 정확도와 절감 효과를 확인한다.
B4: 1. 검증 목적
B5: 목적 | C5: 플랫폼(스마트덱 단열 Layout)이 산출한 단열재 산출면적(주문 판수 × 정척면적)이 현장 실무 산출과 일치하는지(정확도), 실행기준 대비 얼마나 줄이는지(절감 효과)를 3개 현장에서 확인한다.
B6: 대상 현장 | C6: 부산장안 · 남원주1차 · 세종2차 — 단열 지역구분이 서로 달라 두께 구성이 다르다(01_현장조건).
B8: 2. 비교 대상 3종 정의
B9: 실행기준 | C9: 실행예산(내역) 상의 단열재 수량(㎡). 회사 기준 할증(로스)이 포함된 값. 실행 수량이 없으면 '실면적 × (1+실행 할증률)' 로 대체 산정(대체 산정임을 비고에 표기).
B10: 현장산출 | C10: 현장이 직접 작성한 현장식 산출서의 산출면적(㎡) — 두께별 '면적(M2)'.
B11: 플랫폼산출 | C11: 스마트덱 현장식 산출서 CSV 의 산출면적(㎡) = 주문 판수(온장+절단판) × 정척면적. 산출 모드(물량 최소/시공성 우선)를 반드시 기록.
B13: 3. 두께가 다른 현장을 비교하는 원칙
B14: ① 두께별로 따로 비교 | C14: 50T·90T 등은 서로 다른 자재다. 산출면적 비교·오차율·판정은 '현장 × 두께' 단위로 먼저 한다(03_현장별비교).
B15: ② 현장 합계 | C15: 현장 합계는 현장식 산출서 '산출면적 계'와 같게 두께를 합산한 ㎡ 로 비교한다. 두께 비중 차이를 보려면 체적(㎥ = 산출면적 × 두께)을 참고.
B16: ③ 현장 간 비교 지표 | C16: 두께 영향을 받지 않는 '로스율 = 산출면적 ÷ 실면적 − 1' 로 현장끼리 비교한다(04_종합요약). 실면적 = 나누기 전 순수 시공면적.
B17: ④ 지역구분 | C17: 건축물 에너지절약설계기준 지역구분(중부1·중부2·남부)에 따라 외벽 단열 두께가 달라진다. 현장별 적용 두께는 설계도서로 확인해 입력.
B19: 4. 판정 기준 (플랫폼 vs 현장)
B20: 적합 / 검토 / 부적합 | C20: |오차율| ≤ 적합 허용치 → 적합, ≤ 검토 허용치 → 검토, 그 외 부적합. 허용치는 01_현장조건 하단에서 조정(기본 3% / 7%).
B21: 공정 비교 조건 | C21: 세 값이 같은 도면(REV)·같은 범위(동·타입·층)·같은 보드 규격에서 나왔는지 06_검증조건에서 먼저 확인한다. 조건이 다르면 판정 무의미.
B23: 5. 시트 구성과 작성 순서
B24: 01_현장조건 | C24: ① 현장별 지역·두께 구성·보드 규격·산출 모드·실행 할증률 입력
B25: 02_산출입력 | C25: ② 현장 × 동/타입 × 두께 단위로 실행·현장·플랫폼 산출면적(㎡)과 실면적 입력
B26: 03_현장별비교 | C26: 자동 계산 — 두께별 산출면적·오차율·실행 대비 증감·로스율·판수 환산·체적
B27: 04_종합요약 | C27: 자동 계산 — 3개 현장 한 장 요약 + 그래프 (보고용 1페이지)
B28: 05_차이원인 | C28: ③ 차이가 난 두께/겹마다 원인 분류와 조치 기록
B29: 06_검증조건 | C29: ④ 비교 전제 조건 체크리스트 (먼저 확인 권장)
B30: 07_플랫폼원자료 | C30: 플랫폼 현장식 산출서 동별 집계표 원본(근거) — 수정 금지
B32: 6. 범례
B33: 파란 글씨 + 노란 바탕 | C33: 입력 칸 — 직접 채우거나 고치는 곳
B34: 검정 글씨 + 회색 바탕 | C34: 수식 — 고치지 않는다
B35: 초록 글씨 | C35: 다른 시트 값을 그대로 가져온 칸
B36: 플랫폼산출 값 | C36: 3개 현장 최신 REV 를 현재 배포 코드로 계산한 현장식 산출서 CSV 합계(2026-09-30 추출). 원자료는 07_플랫폼원자료.

Sheet 01_현장조건
A1: 01. 현장 조건
A2: 현장별 단열 두께 구성과 산출 조건. 3행 현장명은 다른 시트의 조회 키이므로 바꾸면 02 시트 현장명도 같이 바꿀 것.
A3: 항목 | B3: 부산장안 | C3: 남원주1차 | D3: 세종2차 | E3: 단위 | F3: 설명 / 근거
A4: 지역구분(에너지절약설계기준) | B4: 남부 | C4: 중부1 | D4: 중부2 | F4: 부산=남부, 원주=중부1, 세종=중부2 (일반 기준 — 설계도서로 확인)
A5: 비교 대상 동 / 타입 | B5: 101~104동 전 타입 | C5: 401~405동 전 타입 | D5: 59타입 105~112동 + 84타입 1~22동 | F5: 플랫폼 '동·타입 설정' 매트릭스 전체
A6: 비교 범위 | B6: 전체 419세대 | C6: 전체 900세대 | D6: 전체 1,110세대 (59 320 + 84 790) | F6: 현장식 산출서 '동별 집계표' 합계. 현장산출·실행기준도 같은 범위로
A7: 도면 · 플랫폼 REV | B7: 부산장안 단열재 산출_rev2 · REV 7 | C7: 84A타입(401동~404동) · REV 35 | D7: 세종2차임대 · REV 19(59) + REV 18(84) | F7: 스마트덱 프로젝트명 · 최신 REV
A8: REV 저장일 | B8: 2026-09-28 | C8: 2026-09-17 | D8: 2026-09-22 (두 REV 같은 날) | F8: DB elev_revisions.created_at (KST 기준 날짜는 +9h)
A9: 원본 도면(DXF) | B9: 20260916 부산장안 세대단열재 검토rev2.dxf | C9: 251118_세대단열와리_검토2★.dxf | D9: 59.dxf / 84 타입.dxf | F9: REV 에 첨부된 평면 DXF
A10: 보드 가로(L) | B10: 900 | C10: 1000 | D10: 1000 | E10: mm | F10: REV 저장값
A11: 보드 세로(H) | B11: 2640 | C11: 2600 | D11: 2690 | E11: mm | F11: REV 저장값 (기준층 층고와 같게 설정됨)
A12: 판 면적 | B12: =B10*B11/1000000 -> 2.376 | C12: =C10*C11/1000000 -> 2.6 | D12: =D10*D11/1000000 -> 2.69 | E12: ㎡ | F12: L × H
A13: 직접외기 1P 두께 | B13: 95 | C13: 90 | D13: 70 | E13: T | F13: REV 노출 프리셋
A14: 직접외기 2P 두께 | B14: 55 | C14: 50 | D14: 70 | E14: T | F14: REV 노출 프리셋
A15: 직접외기 총 두께 | B15: =IF(AND(B13="",B14=""),"",N(B13)+N(B14)) -> 150 | C15: =IF(AND(C13="",C14=""),"",N(C13)+N(C14)) -> 140 | D15: =IF(AND(D13="",D14=""),"",N(D13)+N(D14)) -> 140 | E15: T | F15: 1P + 2P
A16: 간접외기 1P 두께 | B16: 55 | C16: 50 | D16: 70 | E16: T | F16: REV 노출 프리셋
A17: 간접외기 2P 두께 | B17: 55 | C17: 50 | D17: 40 | E17: T | F17: REV 노출 프리셋
A18: 간접외기 총 두께 | B18: =IF(AND(B16="",B17=""),"",N(B16)+N(B17)) -> 110 | C18: =IF(AND(C16="",C17=""),"",N(C16)+N(C17)) -> 100 | D18: =IF(AND(D16="",D17=""),"",N(D16)+N(D17)) -> 110 | E18: T | F18: 1P + 2P
A19: 플랫폼 산출 모드 | B19: 물량 최소 | C19: 물량 최소 | D19: 물량 최소 | F19: REV 저장값. 물량 최소 / 시공성 우선 — 모드에 따라 산출면적이 다르다
A20: 버림 기준 폭 | B20: 10 | C20: 50 | D20: 100 | E20: mm | F20: REV 저장값 — 이보다 좁은 자투리는 버림 처리
A21: 최소 조각 폭 | B21: 0 | C21: 100 | D21: 10 | E21: mm | F21: REV 저장값 — 이보다 좁은 조각은 옆 판과 합쳐 재분할
A22: 실행기준 할증률(로스) | E22: % | F22: 실행 수량(㎡)이 없을 때만 '시공면적×(1+할증률)' 대체 산정에 사용
A23: 비교 자재 두께 ① | B23: 95 | C23: 90 | D23: 70 | E23: T | F23: 03 시트에 나올 두께 목록(자재 규격) — 두께가 두꺼운 순
A24: 비교 자재 두께 ② | B24: 55 | C24: 50 | D24: 40 | E24: T
A25: 비교 자재 두께 ③ | E25: T
A26: 플랫폼 산출 추출일 | B26: 2026-09-30 | C26: 2026-09-30 | D26: 2026-09-30 | F26: 최신 REV 를 현재 배포 코드(86e1fa2)로 계산한 현장식 산출서 CSV
A27: 비고 | B27: 구 프로젝트 '부산장안' REV 16 은 07 시트 참고 | C27: 구 프로젝트 '남원주역세권1차' REV 5(401동 2타입)는 07 시트 참고 | D27: 59·84가 한 프로젝트의 서로 다른 REV — 두 REV 합산. 59A 90/50 변 1곳은 '배치 안함'
A30: 판정 기준 (전 현장 공통)
A31: 적합 허용 오차율 (±) | B31: 0.03 | F31: |플랫폼−현장|/현장 이 이하이면 '적합' — 가정값, 보고 전 합의 필요
A32: 검토 허용 오차율 (±) | B32: 0.07 | F32: 이 이하이면 '검토', 초과하면 '부적합' — 가정값

Sheet 02_산출입력
A1: 02. 산출 입력
A2: 한 줄 = 현장 × 동/타입 × 자재 두께. 비교 기준은 산출면적(㎡) = 주문 판수 × 정척면적 (현장식 산출서와 같은 정의). 오른쪽 회색 열은 자동 계산.
A3: 입력 | N3: 자동 계산 (수정 금지)
A4: No | B4: 현장 | C4: 동 / 타입 | D4: 산출 범위 | E4: 반복수 | F4: 자재 두께 (T) | G4: 해당 겹 구성 | H4: 실행기준 산출면적(㎡) | I4: 현장산출 산출면적(㎡) | J4: 플랫폼산출 산출면적(㎡) | K4: 실면적(㎡) 참고·로스율용 | L4: 자료 출처 | M4: 비고 | N4: 판 면적 (㎡) | O4: 실행 적용 (㎡) | P4: 실행 ㎡ ×반복 | Q4: 현장 ㎡ ×반복 | R4: 플랫폼 ㎡ ×반복 | S4: 실면적 ×반복 | T4: 플랫폼 판수 환산
A5: 1 | B5: 부산장안 | C5: 101~104동 전 타입 | D5: 419세대 | E5: 1 | F5: 95 | G5: 직접 1P | H5: 25427 | I5: 29621 | J5: 26884.4 | K5: 25275.36 | L5: 스마트덱 현장식 산출서 CSV (REV 7) | M5: 판수 11,016판 × 2.376㎡ | N5: =IF($B5="","",IFERROR(INDEX('01_현장조건'!$B$12:$D$12,MATCH($B5,'01_현장조건'!$B$3:$D$3,0)),"")) -> 2.376 | O5: =IF($B5="","",IF($H5<>"",$H5,IF(AND($K5<>"",IFERROR(INDEX('01_현장조건'!$B$22:$D$22,MATCH($B5,'01_현장조건'!$B$3:$D$3,0)),"")<>""),$K5*(1+INDEX('01_현장조건'!$B$22:$D$22,MATCH($B5,'01_현장조건'!$B$3:$D$3,0))),""))) -> 25427 | P5: =IF(O5="","",O5*IF($E5="",1,$E5)) -> 25427 | Q5: =IF($I5="","",$I5*IF($E5="",1,$E5)) -> 29621 | R5: =IF($J5="","",$J5*IF($E5="",1,$E5)) -> 26884.4 | S5: =IF($K5="","",$K5*IF($E5="",1,$E5)) -> 25275.36 | T5: =IF(OR(R5="",N5=""),"",ROUND(R5/N5,0)) -> 11315
A6: 2 | B6: 부산장안 | C6: 101~104동 전 타입 | D6: 419세대 | E6: 1 | F6: 55 | G6: 직접 2P · 간접 1P·2P | H6: 48210 | I6: 43244 | J6: 46429.4 | K6: 42151.33 | L6: 스마트덱 현장식 산출서 CSV (REV 7) | M6: 판수 19,458판 × 2.376㎡ | N6: =IF($B6="","",IFERROR(INDEX('01_현장조건'!$B$12:$D$12,MATCH($B6,'01_현장조건'!$B$3:$D$3,0)),"")) -> 2.376 | O6: =IF($B6="","",IF($H6<>"",$H6,IF(AND($K6<>"",IFERROR(INDEX('01_현장조건'!$B$22:$D$22,MATCH($B6,'01_현장조건'!$B$3:$D$3,0)),"")<>""),$K6*(1+INDEX('01_현장조건'!$B$22:$D$22,MATCH($B6,'01_현장조건'!$B$3:$D$3,0))),""))) -> 48210 | P6: =IF(O6="","",O6*IF($E6="",1,$E6)) -> 48210 | Q6: =IF($I6="","",$I6*IF($E6="",1,$E6)) -> 43244 | R6: =IF($J6="","",$J6*IF($E6="",1,$E6)) -> 46429.4 | S6: =IF($K6="","",$K6*IF($E6="",1,$E6)) -> 42151.33 | T6: =IF(OR(R6="",N6=""),"",ROUND(R6/N6,0)) -> 19541
A7: 3 | B7: 남원주1차 | C7: 401~405동 전 타입 | D7: 900세대 | E7: 1 | F7: 90 | G7: 직접 1P | H7: 54657 | I7: 56829 | J7: 54272.4 | K7: 50761.72 | L7: 스마트덱 현장식 산출서 CSV (REV 35) | M7: 판수 20,874판 × 2.6㎡ | N7: =IF($B7="","",IFERROR(INDEX('01_현장조건'!$B$12:$D$12,MATCH($B7,'01_현장조건'!$B$3:$D$3,0)),"")) -> 2.6 | O7: =IF($B7="","",IF($H7<>"",$H7,IF(AND($K7<>"",IFERROR(INDEX('01_현장조건'!$B$22:$D$22,MATCH($B7,'01_현장조건'!$B$3:$D$3,0)),"")<>""),$K7*(1+INDEX('01_현장조건'!$B$22:$D$22,MATCH($B7,'01_현장조건'!$B$3:$D$3,0))),""))) -> 54657 | P7: =IF(O7="","",O7*IF($E7="",1,$E7)) -> 54657 | Q7: =IF($I7="","",$I7*IF($E7="",1,$E7)) -> 56829 | R7: =IF($J7="","",$J7*IF($E7="",1,$E7)) -> 54272.4 | S7: =IF($K7="","",$K7*IF($E7="",1,$E7)) -> 50761.72 | T7: =IF(OR(R7="",N7=""),"",ROUND(R7/N7,0)) -> 20874
A8: 4 | B8: 남원주1차 | C8: 401~405동 전 타입 | D8: 900세대 | E8: 1 | F8: 50 | G8: 직접 2P · 간접 1P·2P | H8: 119761 | I8: 114109 | J8: 117065 | K8: 106128.21 | L8: 스마트덱 현장식 산출서 CSV (REV 35) | M8: 판수 45,025판 × 2.6㎡ | N8: =IF($B8="","",IFERROR(INDEX('01_현장조건'!$B$12:$D$12,MATCH($B8,'01_현장조건'!$B$3:$D$3,0)),"")) -> 2.6 | O8: =IF($B8="","",IF($H8<>"",$H8,IF(AND($K8<>"",IFERROR(INDEX('01_현장조건'!$B$22:$D$22,MATCH($B8,'01_현장조건'!$B$3:$D$3,0)),"")<>""),$K8*(1+INDEX('01_현장조건'!$B$22:$D$22,MATCH($B8,'01_현장조건'!$B$3:$D$3,0))),""))) -> 119761 | P8: =IF(O8="","",O8*IF($E8="",1,$E8)) -> 119761 | Q8: =IF($I8="","",$I8*IF($E8="",1,$E8)) -> 114109 | R8: =IF($J8="","",$J8*IF($E8="",1,$E8)) -> 117065 | S8: =IF($K8="","",$K8*IF($E8="",1,$E8)) -> 106128.21 | T8: =IF(OR(R8="",N8=""),"",ROUND(R8/N8,0)) -> 45025
A9: 5 | B9: 세종2차 | C9: 59+84타입 (59 105~112동 · 84 1~22동) | D9: 1,110세대 | E9: 1 | F9: 70 | G9: 직접 1P·2P · 간접 1P | H9: 170936 | I9: 170936 | J9: =45703.1+128331.83 -> 174034.93 | K9: 163636.09 | L9: 스마트덱 현장식 산출서 CSV (REV 19 · 59.dxf + REV 18 · 84 타입.dxf) | M9: 59·84 합산 (플랫폼 판수 64,697판) | N9: =IF($B9="","",IFERROR(INDEX('01_현장조건'!$B$12:$D$12,MATCH($B9,'01_현장조건'!$B$3:$D$3,0)),"")) -> 2.69 | O9: =IF($B9="","",IF($H9<>"",$H9,IF(AND($K9<>"",IFERROR(INDEX('01_현장조건'!$B$22:$D$22,MATCH($B9,'01_현장조건'!$B$3:$D$3,0)),"")<>""),$K9*(1+INDEX('01_현장조건'!$B$22:$D$22,MATCH($B9,'01_현장조건'!$B$3:$D$3,0))),""))) -> 170936 | P9: =IF(O9="","",O9*IF($E9="",1,$E9)) -> 170936 | Q9: =IF($I9="","",$I9*IF($E9="",1,$E9)) -> 170936 | R9: =IF($J9="","",$J9*IF($E9="",1,$E9)) -> 174034.93 | S9: =IF($K9="","",$K9*IF($E9="",1,$E9)) -> 163636.09 | T9: =IF(OR(R9="",N9=""),"",ROUND(R9/N9,0)) -> 64697
A10: 6 | B10: 세종2차 | C10: 59+84타입 (59 105~112동 · 84 1~22동) | D10: 1,110세대 | E10: 1 | F10: 40 | G10: 간접 2P | H10: 42716 | I10: 42716 | J10: =11300.69+29928.94 -> 41229.63 | K10: 34724.6 | L10: 스마트덱 현장식 산출서 CSV (REV 19 · 59.dxf + REV 18 · 84 타입.dxf) | M10: 59·84 합산 (플랫폼 판수 15,327판) | N10: =IF($B10="","",IFERROR(INDEX('01_현장조건'!$B$12:$D$12,MATCH($B10,'01_현장조건'!$B$3:$D$3,0)),"")) -> 2.69 | O10: =IF($B10="","",IF($H10<>"",$H10,IF(AND($K10<>"",IFERROR(INDEX('01_현장조건'!$B$22:$D$22,MATCH($B10,'01_현장조건'!$B$3:$D$3,0)),"")<>""),$K10*(1+INDEX('01_현장조건'!$B$22:$D$22,MATCH($B10,'01_현장조건'!$B$3:$D$3,0))),""))) -> 42716 | P10: =IF(O10="","",O10*IF($E10="",1,$E10)) -> 42716 | Q10: =IF($I10="","",$I10*IF($E10="",1,$E10)) -> 42716 | R10: =IF($J10="","",$J10*IF($E10="",1,$E10)) -> 41229.63 | S10: =IF($K10="","",$K10*IF($E10="",1,$E10)) -> 34724.6 | T10: =IF(OR(R10="",N10=""),"",ROUND(R10/N10,0)) -> 15327
A11: 9 | N11: =IF($B11="","",IFERROR(INDEX('01_현장조건'!$B$12:$D$12,MATCH($B11,'01_현장조건'!$B$3:$D$3,0)),"")) | O11: =IF($B11="","",IF($H11<>"",$H11,IF(AND($K11<>"",IFERROR(INDEX('01_현장조건'!$B$22:$D$22,MATCH($B11,'01_현장조건'!$B$3:$D$3,0)),"")<>""),$K11*(1+INDEX('01_현장조건'!$B$22:$D$22,MATCH($B11,'01_현장조건'!$B$3:$D$3,0))),""))) | P11: =IF(O11="","",O11*IF($E11="",1,$E11)) | Q11: =IF($I11="","",$I11*IF($E11="",1,$E11)) | R11: =IF($J11="","",$J11*IF($E11="",1,$E11)) | S11: =IF($K11="","",$K11*IF($E11="",1,$E11)) | T11: =IF(OR(R11="",N11=""),"",ROUND(R11/N11,0))
A12: 10 | N12: =IF($B12="","",IFERROR(INDEX('01_현장조건'!$B$12:$D$12,MATCH($B12,'01_현장조건'!$B$3:$D$3,0)),"")) | O12: =IF($B12="","",IF($H12<>"",$H12,IF(AND($K12<>"",IFERROR(INDEX('01_현장조건'!$B$22:$D$22,MATCH($B12,'01_현장조건'!$B$3:$D$3,0)),"")<>""),$K12*(1+INDEX('01_현장조건'!$B$22:$D$22,MATCH($B12,'01_현장조건'!$B$3:$D$3,0))),""))) | P12: =IF(O12="","",O12*IF($E12="",1,$E12)) | Q12: =IF($I12="","",$I12*IF($E12="",1,$E12)) | R12: =IF($J12="","",$J12*IF($E12="",1,$E12)) | S12: =IF($K12="","",$K12*IF($E12="",1,$E12)) | T12: =IF(OR(R12="",N12=""),"",ROUND(R12/N12,0))
A13: 11 | N13: =IF($B13="","",IFERROR(INDEX('01_현장조건'!$B$12:$D$12,MATCH($B13,'01_현장조건'!$B$3:$D$3,0)),"")) | O13: =IF($B13="","",IF($H13<>"",$H13,IF(AND($K13<>"",IFERROR(INDEX('01_현장조건'!$B$22:$D$22,MATCH($B13,'01_현장조건'!$B$3:$D$3,0)),"")<>""),$K13*(1+INDEX('01_현장조건'!$B$22:$D$22,MATCH($B13,'01_현장조건'!$B$3:$D$3,0))),""))) | P13: =IF(O13="","",O13*IF($E13="",1,$E13)) | Q13: =IF($I13="","",$I13*IF($E13="",1,$E13)) | R13: =IF($J13="","",$J13*IF($E13="",1,$E13)) | S13: =IF($K13="","",$K13*IF($E13="",1,$E13)) | T13: =IF(OR(R13="",N13=""),"",ROUND(R13/N13,0))
A14: 12 | N14: =IF($B14="","",IFERROR(INDEX('01_현장조건'!$B$12:$D$12,MATCH($B14,'01_현장조건'!$B$3:$D$3,0)),"")) | O14: =IF($B14="","",IF($H14<>"",$H14,IF(AND($K14<>"",IFERROR(INDEX('01_현장조건'!$B$22:$D$22,MATCH($B14,'01_현장조건'!$B$3:$D$3,0)),"")<>""),$K14*(1+INDEX('01_현장조건'!$B$22:$D$22,MATCH($B14,'01_현장조건'!$B$3:$D$3,0))),""))) | P14: =IF(O14="","",O14*IF($E14="",1,$E14)) | Q14: =IF($I14="","",$I14*IF($E14="",1,$E14)) | R14: =IF($J14="","",$J14*IF($E14="",1,$E14)) | S14: =IF($K14="","",$K14*IF($E14="",1,$E14)) | T14: =IF(OR(R14="",N14=""),"",ROUND(R14/N14,0))
A15: 13 | N15: =IF($B15="","",IFERROR(INDEX('01_현장조건'!$B$12:$D$12,MATCH($B15,'01_현장조건'!$B$3:$D$3,0)),"")) | O15: =IF($B15="","",IF($H15<>"",$H15,IF(AND($K15<>"",IFERROR(INDEX('01_현장조건'!$B$22:$D$22,MATCH($B15,'01_현장조건'!$B$3:$D$3,0)),"")<>""),$K15*(1+INDEX('01_현장조건'!$B$22:$D$22,MATCH($B15,'01_현장조건'!$B$3:$D$3,0))),""))) | P15: =IF(O15="","",O15*IF($E15="",1,$E15)) | Q15: =IF($I15="","",$I15*IF($E15="",1,$E15)) | R15: =IF($J15="","",$J15*IF($E15="",1,$E15)) | S15: =IF($K15="","",$K15*IF($E15="",1,$E15)) | T15: =IF(OR(R15="",N15=""),"",ROUND(R15/N15,0))
A16: 14 | N16: =IF($B16="","",IFERROR(INDEX('01_현장조건'!$B$12:$D$12,MATCH($B16,'01_현장조건'!$B$3:$D$3,0)),"")) | O16: =IF($B16="","",IF($H16<>"",$H16,IF(AND($K16<>"",IFERROR(INDEX('01_현장조건'!$B$22:$D$22,MATCH($B16,'01_현장조건'!$B$3:$D$3,0)),"")<>""),$K16*(1+INDEX('01_현장조건'!$B$22:$D$22,MATCH($B16,'01_현장조건'!$B$3:$D$3,0))),""))) | P16: =IF(O16="","",O16*IF($E16="",1,$E16)) | Q16: =IF($I16="","",$I16*IF($E16="",1,$E16)) | R16: =IF($J16="","",$J16*IF($E16="",1,$E16)) | S16: =IF($K16="","",$K16*IF($E16="",1,$E16)) | T16: =IF(OR(R16="",N16=""),"",ROUND(R16/N16,0))
A17: 15 | N17: =IF($B17="","",IFERROR(INDEX('01_현장조건'!$B$12:$D$12,MATCH($B17,'01_현장조건'!$B$3:$D$3,0)),"")) | O17: =IF($B17="","",IF($H17<>"",$H17,IF(AND($K17<>"",IFERROR(INDEX('01_현장조건'!$B$22:$D$22,MATCH($B17,'01_현장조건'!$B$3:$D$3,0)),"")<>""),$K17*(1+INDEX('01_현장조건'!$B$22:$D$22,MATCH($B17,'01_현장조건'!$B$3:$D$3,0))),""))) | P17: =IF(O17="","",O17*IF($E17="",1,$E17)) | Q17: =IF($I17="","",$I17*IF($E17="",1,$E17)) | R17: =IF($J17="","",$J17*IF($E17="",1,$E17)) | S17: =IF($K17="","",$K17*IF($E17="",1,$E17)) | T17: =IF(OR(R17="",N17=""),"",ROUND(R17/N17,0))
A18: 16 | N18: =IF($B18="","",IFERROR(INDEX('01_현장조건'!$B$12:$D$12,MATCH($B18,'01_현장조건'!$B$3:$D$3,0)),"")) | O18: =IF($B18="","",IF($H18<>"",$H18,IF(AND($K18<>"",IFERROR(INDEX('01_현장조건'!$B$22:$D$22,MATCH($B18,'01_현장조건'!$B$3:$D$3,0)),"")<>""),$K18*(1+INDEX('01_현장조건'!$B$22:$D$22,MATCH($B18,'01_현장조건'!$B$3:$D$3,0))),""))) | P18: =IF(O18="","",O18*IF($E18="",1,$E18)) | Q18: =IF($I18="","",$I18*IF($E18="",1,$E18)) | R18: =IF($J18="","",$J18*IF($E18="",1,$E18)) | S18: =IF($K18="","",$K18*IF($E18="",1,$E18)) | T18: =IF(OR(R18="",N18=""),"",ROUND(R18/N18,0))
A19: 17 | N19: =IF($B19="","",IFERROR(INDEX('01_현장조건'!$B$12:$D$12,MATCH($B19,'01_현장조건'!$B$3:$D$3,0)),"")) | O19: =IF($B19="","",IF($H19<>"",$H19,IF(AND($K19<>"",IFERROR(INDEX('01_현장조건'!$B$22:$D$22,MATCH($B19,'01_현장조건'!$B$3:$D$3,0)),"")<>""),$K19*(1+INDEX('01_현장조건'!$B$22:$D$22,MATCH($B19,'01_현장조건'!$B$3:$D$3,0))),""))) | P19: =IF(O19="","",O19*IF($E19="",1,$E19)) | Q19: =IF($I19="","",$I19*IF($E19="",1,$E19)) | R19: =IF($J19="","",$J19*IF($E19="",1,$E19)) | S19: =IF($K19="","",$K19*IF($E19="",1,$E19)) | T19: =IF(OR(R19="",N19=""),"",ROUND(R19/N19,0))
A20: 18 | N20: =IF($B20="","",IFERROR(INDEX('01_현장조건'!$B$12:$D$12,MATCH($B20,'01_현장조건'!$B$3:$D$3,0)),"")) | O20: =IF($B20="","",IF($H20<>"",$H20,IF(AND($K20<>"",IFERROR(INDEX('01_현장조건'!$B$22:$D$22,MATCH($B20,'01_현장조건'!$B$3:$D$3,0)),"")<>""),$K20*(1+INDEX('01_현장조건'!$B$22:$D$22,MATCH($B20,'01_현장조건'!$B$3:$D$3,0))),""))) | P20: =IF(O20="","",O20*IF($E20="",1,$E20)) | Q20: =IF($I20="","",$I20*IF($E20="",1,$E20)) | R20: =IF($J20="","",$J20*IF($E20="",1,$E20)) | S20: =IF($K20="","",$K20*IF($E20="",1,$E20)) | T20: =IF(OR(R20="",N20=""),"",ROUND(R20/N20,0))
A21: 19 | N21: =IF($B21="","",IFERROR(INDEX('01_현장조건'!$B$12:$D$12,MATCH($B21,'01_현장조건'!$B$3:$D$3,0)),"")) | O21: =IF($B21="","",IF($H21<>"",$H21,IF(AND($K21<>"",IFERROR(INDEX('01_현장조건'!$B$22:$D$22,MATCH($B21,'01_현장조건'!$B$3:$D$3,0)),"")<>""),$K21*(1+INDEX('01_현장조건'!$B$22:$D$22,MATCH($B21,'01_현장조건'!$B$3:$D$3,0))),""))) | P21: =IF(O21="","",O21*IF($E21="",1,$E21)) | Q21: =IF($I21="","",$I21*IF($E21="",1,$E21)) | R21: =IF($J21="","",$J21*IF($E21="",1,$E21)) | S21: =IF($K21="","",$K21*IF($E21="",1,$E21)) | T21: =IF(OR(R21="",N21=""),"",ROUND(R21/N21,0))
A22: 20 | N22: =IF($B22="","",IFERROR(INDEX('01_현장조건'!$B$12:$D$12,MATCH($B22,'01_현장조건'!$B$3:$D$3,0)),"")) | O22: =IF($B22="","",IF($H22<>"",$H22,IF(AND($K22<>"",IFERROR(INDEX('01_현장조건'!$B$22:$D$22,MATCH($B22,'01_현장조건'!$B$3:$D$3,0)),"")<>""),$K22*(1+INDEX('01_현장조건'!$B$22:$D$22,MATCH($B22,'01_현장조건'!$B$3:$D$3,0))),""))) | P22: =IF(O22="","",O22*IF($E22="",1,$E22)) | Q22: =IF($I22="","",$I22*IF($E22="",1,$E22)) | R22: =IF($J22="","",$J22*IF($E22="",1,$E22)) | S22: =IF($K22="","",$K22*IF($E22="",1,$E22)) | T22: =IF(OR(R22="",N22=""),"",ROUND(R22/N22,0))
... A52: 50 | N52: =IF($B52="","",IFERROR(INDEX('01_현장조건'!$B$12:$D$12,MATCH($B52,'01_현장조건'!$B$3:$D$3,0)),"")) | O52: =IF($B52="","",IF($H52<>"",$H52,IF(AND($K52<>"",IFERROR(INDEX('01_현장조건'!$B$22:$D$22,MATCH($B52,'01_현장조건'!$B$3:$D$3,0)),"")<>""),$K52*(1+INDEX('01_현장조건'!$B$22:$D$22,MATCH($B52,'01_현장조건'!$B$3:$D$3,0))),""))) | P52: =IF(O52="","",O52*IF($E52="",1,$E52)) | Q52: =IF($I52="","",$I52*IF($E52="",1,$E52)) | R52: =IF($J52="","",$J52*IF($E52="",1,$E52)) | S52: =IF($K52="","",$K52*IF($E52="",1,$E52)) | T52: =IF(OR(R52="",N52=""),"",ROUND(R52/N52,0))

Sheet 03_현장별비교
A1: 03. 현장별 비교 (두께별)
A2: 자동 계산. 비교 기준 = 산출면적(㎡). 두께별로 먼저 비교하고, 현장 합계는 현장식 산출서 '산출면적 계'와 같은 방식(두께 합산).
B4: ='01_현장조건'!B$3 -> 부산장안 | F4: ="지역 "&'01_현장조건'!B$4&" | "&IF(AND('01_현장조건'!B$13="",'01_현장조건'!B$16=""),"두께 미입력","직접 "&'01_현장조건'!B$13&"+"&'01_현장조건'!B$14&"T / 간접 "&'01_현장조건'!B$16&"+"&'01_현장조건'!B$17&"T")&" | "&'01_현장조건'!B$5&" "&'01_현장조건'!B$6&" | 판 "&'01_현장조건'!B$10&"×"&'01_현장조건'!B$11&" | "&'01_현장조건'!B$19 -> 지역 남부 | 직접 95+55T / 간접 55+55T | 101~104동 전 타입 전체 419세대 | 판 900×2640 | 물량 최소
B5: 자재 | C5: ① 산출면적 ㎡ (비교 기준) | F5: ② SW 정확도 (vs 현장) | I5: ③ SW vs 실행 | K5: ④ 참고 | L5: ⑤ 로스율 (산출÷실면적−1) | O5: ⑥ 판수 환산 (장) | R5: ⑦ 체적 ㎥ (두께 보정)
B6: 두께(T) | C6: 실행기준 | D6: 현장산출 | E6: 플랫폼 | F6: 차이(㎡) | G6: 오차율 | H6: 판정 | I6: 차이(㎡) | J6: 증감률 | K6: 실면적(㎡) | L6: 실행기준 | M6: 현장산출 | N6: 플랫폼 | O6: 실행기준 | P6: 현장산출 | Q6: 플랫폼 | R6: 실행기준 | S6: 현장산출 | T6: 플랫폼
B7: =IF('01_현장조건'!B$23="","",'01_현장조건'!B$23) -> 95 | C7: =IF($B7="","",IF(SUMPRODUCT(('02_산출입력'!$B$5:$B$52=$B$4)*('02_산출입력'!$F$5:$F$52=$B7)*ISNUMBER('02_산출입력'!$P$5:$P$52))=0,"",SUMIFS('02_산출입력'!$P$5:$P$52,'02_산출입력'!$B$5:$B$52,$B$4,'02_산출입력'!$F$5:$F$52,$B7))) -> 25427 | D7: =IF($B7="","",IF(SUMPRODUCT(('02_산출입력'!$B$5:$B$52=$B$4)*('02_산출입력'!$F$5:$F$52=$B7)*ISNUMBER('02_산출입력'!$Q$5:$Q$52))=0,"",SUMIFS('02_산출입력'!$Q$5:$Q$52,'02_산출입력'!$B$5:$B$52,$B$4,'02_산출입력'!$F$5:$F$52,$B7))) -> 29621 | E7: =IF($B7="","",IF(SUMPRODUCT(('02_산출입력'!$B$5:$B$52=$B$4)*('02_산출입력'!$F$5:$F$52=$B7)*ISNUMBER('02_산출입력'!$R$5:$R$52))=0,"",SUMIFS('02_산출입력'!$R$5:$R$52,'02_산출입력'!$B$5:$B$52,$B$4,'02_산출입력'!$F$5:$F$52,$B7))) -> 26884.4 | F7: =IF(OR(D7="",E7=""),"",E7-D7) -> -2736.6 | G7: =IF(OR(F7="",D7=0),"",F7/D7) -> -0.092387158 | H7: =IF(G7="","",IF(ABS(G7)<='01_현장조건'!$B$31,"적합",IF(ABS(G7)<='01_현장조건'!$B$32,"검토","부적합"))) -> 부적합 | I7: =IF(OR(C7="",E7=""),"",E7-C7) -> 1457.4 | J7: =IF(OR(I7="",C7=0),"",I7/C7) -> 0.057317025 | K7: =IF($B7="","",IF(SUMPRODUCT(('02_산출입력'!$B$5:$B$52=$B$4)*('02_산출입력'!$F$5:$F$52=$B7)*ISNUMBER('02_산출입력'!$S$5:$S$52))=0,"",SUMIFS('02_산출입력'!$S$5:$S$52,'02_산출입력'!$B$5:$B$52,$B$4,'02_산출입력'!$F$5:$F$52,$B7))) -> 25275.36 | L7: =IF(OR(C7="",K7="",K7=0),"",C7/K7-1) -> 0.0059995189 | M7: =IF(OR(D7="",K7="",K7=0),"",D7/K7-1) -> 0.17193187 | N7: =IF(OR(E7="",K7="",K7=0),"",E7/K7-1) -> 0.063660419 | O7: =IF(C7="","",ROUND(C7/'01_현장조건'!$B$12,0)) -> 10702 | P7: =IF(D7="","",ROUND(D7/'01_현장조건'!$B$12,0)) -> 12467 | Q7: =IF(E7="","",ROUND(E7/'01_현장조건'!$B$12,0)) -> 11315 | R7: =IF(C7="","",C7*$B7/1000) -> 2415.565 | S7: =IF(D7="","",D7*$B7/1000) -> 2813.995 | T7: =IF(E7="","",E7*$B7/1000) -> 2554.018
B8: =IF('01_현장조건'!B$24="","",'01_현장조건'!B$24) -> 55 | C8: =IF($B8="","",IF(SUMPRODUCT(('02_산출입력'!$B$5:$B$52=$B$4)*('02_산출입력'!$F$5:$F$52=$B8)*ISNUMBER('02_산출입력'!$P$5:$P$52))=0,"",SUMIFS('02_산출입력'!$P$5:$P$52,'02_산출입력'!$B$5:$B$52,$B$4,'02_산출입력'!$F$5:$F$52,$B8))) -> 48210 | D8: =IF($B8="","",IF(SUMPRODUCT(('02_산출입력'!$B$5:$B$52=$B$4)*('02_산출입력'!$F$5:$F$52=$B8)*ISNUMBER('02_산출입력'!$Q$5:$Q$52))=0,"",SUMIFS('02_산출입력'!$Q$5:$Q$52,'02_산출입력'!$B$5:$B$52,$B$4,'02_산출입력'!$F$5:$F$52,$B8))) -> 43244 | E8: =IF($B8="","",IF(SUMPRODUCT(('02_산출입력'!$B$5:$B$52=$B$4)*('02_산출입력'!$F$5:$F$52=$B8)*ISNUMBER('02_산출입력'!$R$5:$R$52))=0,"",SUMIFS('02_산출입력'!$R$5:$R$52,'02_산출입력'!$B$5:$B$52,$B$4,'02_산출입력'!$F$5:$F$52,$B8))) -> 46429.4 | F8: =IF(OR(D8="",E8=""),"",E8-D8) -> 3185.4 | G8: =IF(OR(F8="",D8=0),"",F8/D8) -> 0.073661086 | H8: =IF(G8="","",IF(ABS(G8)<='01_현장조건'!$B$31,"적합",IF(ABS(G8)<='01_현장조건'!$B$32,"검토","부적합"))) -> 부적합 | I8: =IF(OR(C8="",E8=""),"",E8-C8) -> -1780.6 | J8: =IF(OR(I8="",C8=0),"",I8/C8) -> -0.036934246 | K8: =IF($B8="","",IF(SUMPRODUCT(('02_산출입력'!$B$5:$B$52=$B$4)*('02_산출입력'!$F$5:$F$52=$B8)*ISNUMBER('02_산출입력'!$S$5:$S$52))=0,"",SUMIFS('02_산출입력'!$S$5:$S$52,'02_산출입력'!$B$5:$B$52,$B$4,'02_산출입력'!$F$5:$F$52,$B8))) -> 42151.33 | L8: =IF(OR(C8="",K8="",K8=0),"",C8/K8-1) -> 0.14373615 | M8: =IF(OR(D8="",K8="",K8=0),"",D8/K8-1) -> 0.025922551 | N8: =IF(OR(E8="",K8="",K8=0),"",E8/K8-1) -> 0.10149312 | O8: =IF(C8="","",ROUND(C8/'01_현장조건'!$B$12,0)) -> 20290 | P8: =IF(D8="","",ROUND(D8/'01_현장조건'!$B$12,0)) -> 18200 | Q8: =IF(E8="","",ROUND(E8/'01_현장조건'!$B$12,0)) -> 19541 | R8: =IF(C8="","",C8*$B8/1000) -> 2651.55 | S8: =IF(D8="","",D8*$B8/1000) -> 2378.42 | T8: =IF(E8="","",E8*$B8/1000) -> 2553.617
B9: =IF('01_현장조건'!B$25="","",'01_현장조건'!B$25) | C9: =IF($B9="","",IF(SUMPRODUCT(('02_산출입력'!$B$5:$B$52=$B$4)*('02_산출입력'!$F$5:$F$52=$B9)*ISNUMBER('02_산출입력'!$P$5:$P$52))=0,"",SUMIFS('02_산출입력'!$P$5:$P$52,'02_산출입력'!$B$5:$B$52,$B$4,'02_산출입력'!$F$5:$F$52,$B9))) | D9: =IF($B9="","",IF(SUMPRODUCT(('02_산출입력'!$B$5:$B$52=$B$4)*('02_산출입력'!$F$5:$F$52=$B9)*ISNUMBER('02_산출입력'!$Q$5:$Q$52))=0,"",SUMIFS('02_산출입력'!$Q$5:$Q$52,'02_산출입력'!$B$5:$B$52,$B$4,'02_산출입력'!$F$5:$F$52,$B9))) | E9: =IF($B9="","",IF(SUMPRODUCT(('02_산출입력'!$B$5:$B$52=$B$4)*('02_산출입력'!$F$5:$F$52=$B9)*ISNUMBER('02_산출입력'!$R$5:$R$52))=0,"",SUMIFS('02_산출입력'!$R$5:$R$52,'02_산출입력'!$B$5:$B$52,$B$4,'02_산출입력'!$F$5:$F$52,$B9))) | F9: =IF(OR(D9="",E9=""),"",E9-D9) | G9: =IF(OR(F9="",D9=0),"",F9/D9) | H9: =IF(G9="","",IF(ABS(G9)<='01_현장조건'!$B$31,"적합",IF(ABS(G9)<='01_현장조건'!$B$32,"검토","부적합"))) | I9: =IF(OR(C9="",E9=""),"",E9-C9) | J9: =IF(OR(I9="",C9=0),"",I9/C9) | K9: =IF($B9="","",IF(SUMPRODUCT(('02_산출입력'!$B$5:$B$52=$B$4)*('02_산출입력'!$F$5:$F$52=$B9)*ISNUMBER('02_산출입력'!$S$5:$S$52))=0,"",SUMIFS('02_산출입력'!$S$5:$S$52,'02_산출입력'!$B$5:$B$52,$B$4,'02_산출입력'!$F$5:$F$52,$B9))) | L9: =IF(OR(C9="",K9="",K9=0),"",C9/K9-1) | M9: =IF(OR(D9="",K9="",K9=0),"",D9/K9-1) | N9: =IF(OR(E9="",K9="",K9=0),"",E9/K9-1) | O9: =IF(C9="","",ROUND(C9/'01_현장조건'!$B$12,0)) | P9: =IF(D9="","",ROUND(D9/'01_현장조건'!$B$12,0)) | Q9: =IF(E9="","",ROUND(E9/'01_현장조건'!$B$12,0)) | R9: =IF(C9="","",C9*$B9/1000) | S9: =IF(D9="","",D9*$B9/1000) | T9: =IF(E9="","",E9*$B9/1000)
B10: 현장 합계 | C10: =IF(COUNT(C7:C9)=0,"",SUM(C7:C9)) -> 73637 | D10: =IF(COUNT(D7:D9)=0,"",SUM(D7:D9)) -> 72865 | E10: =IF(COUNT(E7:E9)=0,"",SUM(E7:E9)) -> 73313.8 | F10: =IF(OR(D10="",E10=""),"",E10-D10) -> 448.8 | G10: =IF(OR(F10="",D10=0),"",F10/D10) -> 0.0061593358 | H10: =IF(G10="","",IF(ABS(G10)<='01_현장조건'!$B$31,"적합",IF(ABS(G10)<='01_현장조건'!$B$32,"검토","부적합"))) -> 적합 | I10: =IF(OR(C10="",E10=""),"",E10-C10) -> -323.2 | J10: =IF(OR(I10="",C10=0),"",I10/C10) -> -0.0043890979 | K10: =IF(COUNT(K7:K9)=0,"",SUM(K7:K9)) -> 67426.69 | L10: =IF(OR(C10="",K10="",K10=0),"",C10/K10-1) -> 0.092104625 | M10: =IF(OR(D10="",K10="",K10=0),"",D10/K10-1) -> 0.080655153 | N10: =IF(OR(E10="",K10="",K10=0),"",E10/K10-1) -> 0.087311271 | O10: =IF(COUNT(O7:O9)=0,"",SUM(O7:O9)) -> 30992 | P10: =IF(COUNT(P7:P9)=0,"",SUM(P7:P9)) -> 30667 | Q10: =IF(COUNT(Q7:Q9)=0,"",SUM(Q7:Q9)) -> 30856 | R10: =IF(COUNT(R7:R9)=0,"",SUM(R7:R9)) -> 5067.115 | S10: =IF(COUNT(S7:S9)=0,"",SUM(S7:S9)) -> 5192.415 | T10: =IF(COUNT(T7:T9)=0,"",SUM(T7:T9)) -> 5107.635
B11: ※ 산출면적 = 주문 판수 × 정척면적(현장식 산출서 '면적(M2)'). 합계는 산출서 '산출면적 계'와 같다. 판정은 두께별 행을 먼저 본다(두께가 다르면 다른 자재). 체적은 두께 차이 보정용 참고.
B13: ='01_현장조건'!C$3 -> 남원주1차 | F13: ="지역 "&'01_현장조건'!C$4&" | "&IF(AND('01_현장조건'!C$13="",'01_현장조건'!C$16=""),"두께 미입력","직접 "&'01_현장조건'!C$13&"+"&'01_현장조건'!C$14&"T / 간접 "&'01_현장조건'!C$16&"+"&'01_현장조건'!C$17&"T")&" | "&'01_현장조건'!C$5&" "&'01_현장조건'!C$6&" | 판 "&'01_현장조건'!C$10&"×"&'01_현장조건'!C$11&" | "&'01_현장조건'!C$19 -> 지역 중부1 | 직접 90+50T / 간접 50+50T | 401~405동 전 타입 전체 900세대 | 판 1000×2600 | 물량 최소
B14: 자재 | C14: ① 산출면적 ㎡ (비교 기준) | F14: ② SW 정확도 (vs 현장) | I14: ③ SW vs 실행 | K14: ④ 참고 | L14: ⑤ 로스율 (산출÷실면적−1) | O14: ⑥ 판수 환산 (장) | R14: ⑦ 체적 ㎥ (두께 보정)
B15: 두께(T) | C15: 실행기준 | D15: 현장산출 | E15: 플랫폼 | F15: 차이(㎡) | G15: 오차율 | H15: 판정 | I15: 차이(㎡) | J15: 증감률 | K15: 실면적(㎡) | L15: 실행기준 | M15: 현장산출 | N15: 플랫폼 | O15: 실행기준 | P15: 현장산출 | Q15: 플랫폼 | R15: 실행기준 | S15: 현장산출 | T15: 플랫폼
B16: =IF('01_현장조건'!C$23="","",'01_현장조건'!C$23) -> 90 | C16: =IF($B16="","",IF(SUMPRODUCT(('02_산출입력'!$B$5:$B$52=$B$13)*('02_산출입력'!$F$5:$F$52=$B16)*ISNUMBER('02_산출입력'!$P$5:$P$52))=0,"",SUMIFS('02_산출입력'!$P$5:$P$52,'02_산출입력'!$B$5:$B$52,$B$13,'02_산출입력'!$F$5:$F$52,$B16))) -> 54657 | D16: =IF($B16="","",IF(SUMPRODUCT(('02_산출입력'!$B$5:$B$52=$B$13)*('02_산출입력'!$F$5:$F$52=$B16)*ISNUMBER('02_산출입력'!$Q$5:$Q$52))=0,"",SUMIFS('02_산출입력'!$Q$5:$Q$52,'02_산출입력'!$B$5:$B$52,$B$13,'02_산출입력'!$F$5:$F$52,$B16))) -> 56829 | E16: =IF($B16="","",IF(SUMPRODUCT(('02_산출입력'!$B$5:$B$52=$B$13)*('02_산출입력'!$F$5:$F$52=$B16)*ISNUMBER('02_산출입력'!$R$5:$R$52))=0,"",SUMIFS('02_산출입력'!$R$5:$R$52,'02_산출입력'!$B$5:$B$52,$B$13,'02_산출입력'!$F$5:$F$52,$B16))) -> 54272.4 | F16: =IF(OR(D16="",E16=""),"",E16-D16) -> -2556.6 | G16: =IF(OR(F16="",D16=0),"",F16/D16) -> -0.044987594 | H16: =IF(G16="","",IF(ABS(G16)<='01_현장조건'!$B$31,"적합",IF(ABS(G16)<='01_현장조건'!$B$32,"검토","부적합"))) -> 검토 | I16: =IF(OR(C16="",E16=""),"",E16-C16) -> -384.6 | J16: =IF(OR(I16="",C16=0),"",I16/C16) -> -0.0070366101 | K16: =IF($B16="","",IF(SUMPRODUCT(('02_산출입력'!$B$5:$B$52=$B$13)*('02_산출입력'!$F$5:$F$52=$B16)*ISNUMBER('02_산출입력'!$S$5:$S$52))=0,"",SUMIFS('02_산출입력'!$S$5:$S$52,'02_산출입력'!$B$5:$B$52,$B$13,'02_산출입력'!$F$5:$F$52,$B16))) -> 50761.72 | L16: =IF(OR(C16="",K16="",K16=0),"",C16/K16-1) -> 0.076736564 | M16: =IF(OR(D16="",K16="",K16=0),"",D16/K16-1) -> 0.11952471 | N16: =IF(OR(E16="",K16="",K16=0),"",E16/K16-1) -> 0.069159989 | O16: =IF(C16="","",ROUND(C16/'01_현장조건'!$C$12,0)) -> 21022 | P16: =IF(D16="","",ROUND(D16/'01_현장조건'!$C$12,0)) -> 21857 | Q16: =IF(E16="","",ROUND(E16/'01_현장조건'!$C$12,0)) -> 20874 | R16: =IF(C16="","",C16*$B16/1000) -> 4919.13 | S16: =IF(D16="","",D16*$B16/1000) -> 5114.61 | T16: =IF(E16="","",E16*$B16/1000) -> 4884.516
B17: =IF('01_현장조건'!C$24="","",'01_현장조건'!C$24) -> 50 | C17: =IF($B17="","",IF(SUMPRODUCT(('02_산출입력'!$B$5:$B$52=$B$13)*('02_산출입력'!$F$5:$F$52=$B17)*ISNUMBER('02_산출입력'!$P$5:$P$52))=0,"",SUMIFS('02_산출입력'!$P$5:$P$52,'02_산출입력'!$B$5:$B$52,$B$13,'02_산출입력'!$F$5:$F$52,$B17))) -> 119761 | D17: =IF($B17="","",IF(SUMPRODUCT(('02_산출입력'!$B$5:$B$52=$B$13)*('02_산출입력'!$F$5:$F$52=$B17)*ISNUMBER('02_산출입력'!$Q$5:$Q$52))=0,"",SUMIFS('02_산출입력'!$Q$5:$Q$52,'02_산출입력'!$B$5:$B$52,$B$13,'02_산출입력'!$F$5:$F$52,$B17))) -> 114109 | E17: =IF($B17="","",IF(SUMPRODUCT(('02_산출입력'!$B$5:$B$52=$B$13)*('02_산출입력'!$F$5:$F$52=$B17)*ISNUMBER('02_산출입력'!$R$5:$R$52))=0,"",SUMIFS('02_산출입력'!$R$5:$R$52,'02_산출입력'!$B$5:$B$52,$B$13,'02_산출입력'!$F$5:$F$52,$B17))) -> 117065 | F17: =IF(OR(D17="",E17=""),"",E17-D17) -> 2956 | G17: =IF(OR(F17="",D17=0),"",F17/D17) -> 0.025905056 | H17: =IF(G17="","",IF(ABS(G17)<='01_현장조건'!$B$31,"적합",IF(ABS(G17)<='01_현장조건'!$B$32,"검토","부적합"))) -> 적합 | I17: =IF(OR(C17="",E17=""),"",E17-C17) -> -2696 | J17: =IF(OR(I17="",C17=0),"",I17/C17) -> -0.022511502 | K17: =IF($B17="","",IF(SUMPRODUCT(('02_산출입력'!$B$5:$B$52=$B$13)*('02_산출입력'!$F$5:$F$52=$B17)*ISNUMBER('02_산출입력'!$S$5:$S$52))=0,"",SUMIFS('02_산출입력'!$S$5:$S$52,'02_산출입력'!$B$5:$B$52,$B$13,'02_산출입력'!$F$5:$F$52,$B17))) -> 106128.21 | L17: =IF(OR(C17="",K17="",K17=0),"",C17/K17-1) -> 0.12845586 | M17: =IF(OR(D17="",K17="",K17=0),"",D17/K17-1) -> 0.075199516 | N17: =IF(OR(E17="",K17="",K17=0),"",E17/K17-1) -> 0.10305262 | O17: =IF(C17="","",ROUND(C17/'01_현장조건'!$C$12,0)) -> 46062 | P17: =IF(D17="","",ROUND(D17/'01_현장조건'!$C$12,0)) -> 43888 | Q17: =IF(E17="","",ROUND(E17/'01_현장조건'!$C$12,0)) -> 45025 | R17: =IF(C17="","",C17*$B17/1000) -> 5988.05 | S17: =IF(D17="","",D17*$B17/1000) -> 5705.45 | T17: =IF(E17="","",E17*$B17/1000) -> 5853.25
B18: =IF('01_현장조건'!C$25="","",'01_현장조건'!C$25) | C18: =IF($B18="","",IF(SUMPRODUCT(('02_산출입력'!$B$5:$B$52=$B$13)*('02_산출입력'!$F$5:$F$52=$B18)*ISNUMBER('02_산출입력'!$P$5:$P$52))=0,"",SUMIFS('02_산출입력'!$P$5:$P$52,'02_산출입력'!$B$5:$B$52,$B$13,'02_산출입력'!$F$5:$F$52,$B18))) | D18: =IF($B18="","",IF(SUMPRODUCT(('02_산출입력'!$B$5:$B$52=$B$13)*('02_산출입력'!$F$5:$F$52=$B18)*ISNUMBER('02_산출입력'!$Q$5:$Q$52))=0,"",SUMIFS('02_산출입력'!$Q$5:$Q$52,'02_산출입력'!$B$5:$B$52,$B$13,'02_산출입력'!$F$5:$F$52,$B18))) | E18: =IF($B18="","",IF(SUMPRODUCT(('02_산출입력'!$B$5:$B$52=$B$13)*('02_산출입력'!$F$5:$F$52=$B18)*ISNUMBER('02_산출입력'!$R$5:$R$52))=0,"",SUMIFS('02_산출입력'!$R$5:$R$52,'02_산출입력'!$B$5:$B$52,$B$13,'02_산출입력'!$F$5:$F$52,$B18))) | F18: =IF(OR(D18="",E18=""),"",E18-D18) | G18: =IF(OR(F18="",D18=0),"",F18/D18) | H18: =IF(G18="","",IF(ABS(G18)<='01_현장조건'!$B$31,"적합",IF(ABS(G18)<='01_현장조건'!$B$32,"검토","부적합"))) | I18: =IF(OR(C18="",E18=""),"",E18-C18) | J18: =IF(OR(I18="",C18=0),"",I18/C18) | K18: =IF($B18="","",IF(SUMPRODUCT(('02_산출입력'!$B$5:$B$52=$B$13)*('02_산출입력'!$F$5:$F$52=$B18)*ISNUMBER('02_산출입력'!$S$5:$S$52))=0,"",SUMIFS('02_산출입력'!$S$5:$S$52,'02_산출입력'!$B$5:$B$52,$B$13,'02_산출입력'!$F$5:$F$52,$B18))) | L18: =IF(OR(C18="",K18="",K18=0),"",C18/K18-1) | M18: =IF(OR(D18="",K18="",K18=0),"",D18/K18-1) | N18: =IF(OR(E18="",K18="",K18=0),"",E18/K18-1) | O18: =IF(C18="","",ROUND(C18/'01_현장조건'!$C$12,0)) | P18: =IF(D18="","",ROUND(D18/'01_현장조건'!$C$12,0)) | Q18: =IF(E18="","",ROUND(E18/'01_현장조건'!$C$12,0)) | R18: =IF(C18="","",C18*$B18/1000) | S18: =IF(D18="","",D18*$B18/1000) | T18: =IF(E18="","",E18*$B18/1000)
B19: 현장 합계 | C19: =IF(COUNT(C16:C18)=0,"",SUM(C16:C18)) -> 174418 | D19: =IF(COUNT(D16:D18)=0,"",SUM(D16:D18)) -> 170938 | E19: =IF(COUNT(E16:E18)=0,"",SUM(E16:E18)) -> 171337.4 | F19: =IF(OR(D19="",E19=""),"",E19-D19) -> 399.4 | G19: =IF(OR(F19="",D19=0),"",F19/D19) -> 0.0023365197 | H19: =IF(G19="","",IF(ABS(G19)<='01_현장조건'!$B$31,"적합",IF(ABS(G19)<='01_현장조건'!$B$32,"검토","부적합"))) -> 적합 | I19: =IF(OR(C19="",E19=""),"",E19-C19) -> -3080.6 | J19: =IF(OR(I19="",C19=0),"",I19/C19) -> -0.017662168 | K19: =IF(COUNT(K16:K18)=0,"",SUM(K16:K18)) -> 156889.93 | L19: =IF(OR(C19="",K19="",K19=0),"",C19/K19-1) -> 0.11172208 | M19: =IF(OR(D19="",K19="",K19=0),"",D19/K19-1) -> 0.089540928 | N19: =IF(OR(E19="",K19="",K19=0),"",E19/K19-1) -> 0.092086662 | O19: =IF(COUNT(O16:O18)=0,"",SUM(O16:O18)) -> 67084 | P19: =IF(COUNT(P16:P18)=0,"",SUM(P16:P18)) -> 65745 | Q19: =IF(COUNT(Q16:Q18)=0,"",SUM(Q16:Q18)) -> 65899 | R19: =IF(COUNT(R16:R18)=0,"",SUM(R16:R18)) -> 10907.18 | S19: =IF(COUNT(S16:S18)=0,"",SUM(S16:S18)) -> 10820.06 | T19: =IF(COUNT(T16:T18)=0,"",SUM(T16:T18)) -> 10737.766
B20: ※ 산출면적 = 주문 판수 × 정척면적(현장식 산출서 '면적(M2)'). 합계는 산출서 '산출면적 계'와 같다. 판정은 두께별 행을 먼저 본다(두께가 다르면 다른 자재). 체적은 두께 차이 보정용 참고.
B22: ='01_현장조건'!D$3 -> 세종2차 | F22: ="지역 "&'01_현장조건'!D$4&" | "&IF(AND('01_현장조건'!D$13="",'01_현장조건'!D$16=""),"두께 미입력","직접 "&'01_현장조건'!D$13&"+"&'01_현장조건'!D$14&"T / 간접 "&'01_현장조건'!D$16&"+"&'01_현장조건'!D$17&"T")&" | "&'01_현장조건'!D$5&" "&'01_현장조건'!D$6&" | 판 "&'01_현장조건'!D$10&"×"&'01_현장조건'!D$11&" | "&'01_현장조건'!D$19 -> 지역 중부2 | 직접 70+70T / 간접 70+40T | 59타입 105~112동 + 84타입 1~22동 전체 1,110세대 (59 320 + 84 790) | 판 1000×2690 | 물량 최소
B23: 자재 | C23: ① 산출면적 ㎡ (비교 기준) | F23: ② SW 정확도 (vs 현장) | I23: ③ SW vs 실행 | K23: ④ 참고 | L23: ⑤ 로스율 (산출÷실면적−1) | O23: ⑥ 판수 환산 (장) | R23: ⑦ 체적 ㎥ (두께 보정)
B24: 두께(T) | C24: 실행기준 | D24: 현장산출 | E24: 플랫폼 | F24: 차이(㎡) | G24: 오차율 | H24: 판정 | I24: 차이(㎡) | J24: 증감률 | K24: 실면적(㎡) | L24: 실행기준 | M24: 현장산출 | N24: 플랫폼 | O24: 실행기준 | P24: 현장산출 | Q24: 플랫폼 | R24: 실행기준 | S24: 현장산출 | T24: 플랫폼
B25: =IF('01_현장조건'!D$23="","",'01_현장조건'!D$23) -> 70 | C25: =IF($B25="","",IF(SUMPRODUCT(('02_산출입력'!$B$5:$B$52=$B$22)*('02_산출입력'!$F$5:$F$52=$B25)*ISNUMBER('02_산출입력'!$P$5:$P$52))=0,"",SUMIFS('02_산출입력'!$P$5:$P$52,'02_산출입력'!$B$5:$B$52,$B$22,'02_산출입력'!$F$5:$F$52,$B25))) -> 170936 | D25: =IF($B25="","",IF(SUMPRODUCT(('02_산출입력'!$B$5:$B$52=$B$22)*('02_산출입력'!$F$5:$F$52=$B25)*ISNUMBER('02_산출입력'!$Q$5:$Q$52))=0,"",SUMIFS('02_산출입력'!$Q$5:$Q$52,'02_산출입력'!$B$5:$B$52,$B$22,'02_산출입력'!$F$5:$F$52,$B25))) -> 170936 | E25: =IF($B25="","",IF(SUMPRODUCT(('02_산출입력'!$B$5:$B$52=$B$22)*('02_산출입력'!$F$5:$F$52=$B25)*ISNUMBER('02_산출입력'!$R$5:$R$52))=0,"",SUMIFS('02_산출입력'!$R$5:$R$52,'02_산출입력'!$B$5:$B$52,$B$22,'02_산출입력'!$F$5:$F$52,$B25))) -> 174034.93 | F25: =IF(OR(D25="",E25=""),"",E25-D25) -> 3098.93 | G25: =IF(OR(F25="",D25=0),"",F25/D25) -> 0.018129183 | H25: =IF(G25="","",IF(ABS(G25)<='01_현장조건'!$B$31,"적합",IF(ABS(G25)<='01_현장조건'!$B$32,"검토","부적합"))) -> 적합 | I25: =IF(OR(C25="",E25=""),"",E25-C25) -> 3098.93 | J25: =IF(OR(I25="",C25=0),"",I25/C25) -> 0.018129183 | K25: =IF($B25="","",IF(SUMPRODUCT(('02_산출입력'!$B$5:$B$52=$B$22)*('02_산출입력'!$F$5:$F$52=$B25)*ISNUMBER('02_산출입력'!$S$5:$S$52))=0,"",SUMIFS('02_산출입력'!$S$5:$S$52,'02_산출입력'!$B$5:$B$52,$B$22,'02_산출입력'!$F$5:$F$52,$B25))) -> 163636.09 | L25: =IF(OR(C25="",K25="",K25=0),"",C25/K25-1) -> 0.044610636 | M25: =IF(OR(D25="",K25="",K25=0),"",D25/K25-1) -> 0.044610636 | N25: =IF(OR(E25="",K25="",K25=0),"",E25/K25-1) -> 0.063548573 | O25: =IF(C25="","",ROUND(C25/'01_현장조건'!$D$12,0)) -> 63545 | P25: =IF(D25="","",ROUND(D25/'01_현장조건'!$D$12,0)) -> 63545 | Q25: =IF(E25="","",ROUND(E25/'01_현장조건'!$D$12,0)) -> 64697 | R25: =IF(C25="","",C25*$B25/1000) -> 11965.52 | S25: =IF(D25="","",D25*$B25/1000) -> 11965.52 | T25: =IF(E25="","",E25*$B25/1000) -> 12182.445
B26: =IF('01_현장조건'!D$24="","",'01_현장조건'!D$24) -> 40 | C26: =IF($B26="","",IF(SUMPRODUCT(('02_산출입력'!$B$5:$B$52=$B$22)*('02_산출입력'!$F$5:$F$52=$B26)*ISNUMBER('02_산출입력'!$P$5:$P$52))=0,"",SUMIFS('02_산출입력'!$P$5:$P$52,'02_산출입력'!$B$5:$B$52,$B$22,'02_산출입력'!$F$5:$F$52,$B26))) -> 42716 | D26: =IF($B26="","",IF(SUMPRODUCT(('02_산출입력'!$B$5:$B$52=$B$22)*('02_산출입력'!$F$5:$F$52=$B26)*ISNUMBER('02_산출입력'!$Q$5:$Q$52))=0,"",SUMIFS('02_산출입력'!$Q$5:$Q$52,'02_산출입력'!$B$5:$B$52,$B$22,'02_산출입력'!$F$5:$F$52,$B26))) -> 42716 | E26: =IF($B26="","",IF(SUMPRODUCT(('02_산출입력'!$B$5:$B$52=$B$22)*('02_산출입력'!$F$5:$F$52=$B26)*ISNUMBER('02_산출입력'!$R$5:$R$52))=0,"",SUMIFS('02_산출입력'!$R$5:$R$52,'02_산출입력'!$B$5:$B$52,$B$22,'02_산출입력'!$F$5:$F$52,$B26))) -> 41229.63 | F26: =IF(OR(D26="",E26=""),"",E26-D26) -> -1486.37 | G26: =IF(OR(F26="",D26=0),"",F26/D26) -> -0.034796563 | H26: =IF(G26="","",IF(ABS(G26)<='01_현장조건'!$B$31,"적합",IF(ABS(G26)<='01_현장조건'!$B$32,"검토","부적합"))) -> 검토 | I26: =IF(OR(C26="",E26=""),"",E26-C26) -> -1486.37 | J26: =IF(OR(I26="",C26=0),"",I26/C26) -> -0.034796563 | K26: =IF($B26="","",IF(SUMPRODUCT(('02_산출입력'!$B$5:$B$52=$B$22)*('02_산출입력'!$F$5:$F$52=$B26)*ISNUMBER('02_산출입력'!$S$5:$S$52))=0,"",SUMIFS('02_산출입력'!$S$5:$S$52,'02_산출입력'!$B$5:$B$52,$B$22,'02_산출입력'!$F$5:$F$52,$B26))) -> 34724.6 | L26: =IF(OR(C26="",K26="",K26=0),"",C26/K26-1) -> 0.23013656 | M26: =IF(OR(D26="",K26="",K26=0),"",D26/K26-1) -> 0.23013656 | N26: =IF(OR(E26="",K26="",K26=0),"",E26/K26-1) -> 0.18733204 | O26: =IF(C26="","",ROUND(C26/'01_현장조건'!$D$12,0)) -> 15880 | P26: =IF(D26="","",ROUND(D26/'01_현장조건'!$D$12,0)) -> 15880 | Q26: =IF(E26="","",ROUND(E26/'01_현장조건'!$D$12,0)) -> 15327 | R26: =IF(C26="","",C26*$B26/1000) -> 1708.64 | S26: =IF(D26="","",D26*$B26/1000) -> 1708.64 | T26: =IF(E26="","",E26*$B26/1000) -> 1649.1852
B27: =IF('01_현장조건'!D$25="","",'01_현장조건'!D$25) | C27: =IF($B27="","",IF(SUMPRODUCT(('02_산출입력'!$B$5:$B$52=$B$22)*('02_산출입력'!$F$5:$F$52=$B27)*ISNUMBER('02_산출입력'!$P$5:$P$52))=0,"",SUMIFS('02_산출입력'!$P$5:$P$52,'02_산출입력'!$B$5:$B$52,$B$22,'02_산출입력'!$F$5:$F$52,$B27))) | D27: =IF($B27="","",IF(SUMPRODUCT(('02_산출입력'!$B$5:$B$52=$B$22)*('02_산출입력'!$F$5:$F$52=$B27)*ISNUMBER('02_산출입력'!$Q$5:$Q$52))=0,"",SUMIFS('02_산출입력'!$Q$5:$Q$52,'02_산출입력'!$B$5:$B$52,$B$22,'02_산출입력'!$F$5:$F$52,$B27))) | E27: =IF($B27="","",IF(SUMPRODUCT(('02_산출입력'!$B$5:$B$52=$B$22)*('02_산출입력'!$F$5:$F$52=$B27)*ISNUMBER('02_산출입력'!$R$5:$R$52))=0,"",SUMIFS('02_산출입력'!$R$5:$R$52,'02_산출입력'!$B$5:$B$52,$B$22,'02_산출입력'!$F$5:$F$52,$B27))) | F27: =IF(OR(D27="",E27=""),"",E27-D27) | G27: =IF(OR(F27="",D27=0),"",F27/D27) | H27: =IF(G27="","",IF(ABS(G27)<='01_현장조건'!$B$31,"적합",IF(ABS(G27)<='01_현장조건'!$B$32,"검토","부적합"))) | I27: =IF(OR(C27="",E27=""),"",E27-C27) | J27: =IF(OR(I27="",C27=0),"",I27/C27) | K27: =IF($B27="","",IF(SUMPRODUCT(('02_산출입력'!$B$5:$B$52=$B$22)*('02_산출입력'!$F$5:$F$52=$B27)*ISNUMBER('02_산출입력'!$S$5:$S$52))=0,"",SUMIFS('02_산출입력'!$S$5:$S$52,'02_산출입력'!$B$5:$B$52,$B$22,'02_산출입력'!$F$5:$F$52,$B27))) | L27: =IF(OR(C27="",K27="",K27=0),"",C27/K27-1) | M27: =IF(OR(D27="",K27="",K27=0),"",D27/K27-1) | N27: =IF(OR(E27="",K27="",K27=0),"",E27/K27-1) | O27: =IF(C27="","",ROUND(C27/'01_현장조건'!$D$12,0)) | P27: =IF(D27="","",ROUND(D27/'01_현장조건'!$D$12,0)) | Q27: =IF(E27="","",ROUND(E27/'01_현장조건'!$D$12,0)) | R27: =IF(C27="","",C27*$B27/1000) | S27: =IF(D27="","",D27*$B27/1000) | T27: =IF(E27="","",E27*$B27/1000)
B28: 현장 합계 | C28: =IF(COUNT(C25:C27)=0,"",SUM(C25:C27)) -> 213652 | D28: =IF(COUNT(D25:D27)=0,"",SUM(D25:D27)) -> 213652 | E28: =IF(COUNT(E25:E27)=0,"",SUM(E25:E27)) -> 215264.56 | F28: =IF(OR(D28="",E28=""),"",E28-D28) -> 1612.56 | G28: =IF(OR(F28="",D28=0),"",F28/D28) -> 0.0075476008 | H28: =IF(G28="","",IF(ABS(G28)<='01_현장조건'!$B$31,"적합",IF(ABS(G28)<='01_현장조건'!$B$32,"검토","부적합"))) -> 적합 | I28: =IF(OR(C28="",E28=""),"",E28-C28) -> 1612.56 | J28: =IF(OR(I28="",C28=0),"",I28/C28) -> 0.0075476008 | K28: =IF(COUNT(K25:K27)=0,"",SUM(K25:K27)) -> 198360.69 | L28: =IF(OR(C28="",K28="",K28=0),"",C28/K28-1) -> 0.077088409 | M28: =IF(OR(D28="",K28="",K28=0),"",D28/K28-1) -> 0.077088409 | N28: =IF(OR(E28="",K28="",K28=0),"",E28/K28-1) -> 0.085217842 | O28: =IF(COUNT(O25:O27)=0,"",SUM(O25:O27)) -> 79425 | P28: =IF(COUNT(P25:P27)=0,"",SUM(P25:P27)) -> 79425 | Q28: =IF(COUNT(Q25:Q27)=0,"",SUM(Q25:Q27)) -> 80024 | R28: =IF(COUNT(R25:R27)=0,"",SUM(R25:R27)) -> 13674.16 | S28: =IF(COUNT(S25:S27)=0,"",SUM(S25:S27)) -> 13674.16 | T28: =IF(COUNT(T25:T27)=0,"",SUM(T25:T27)) -> 13831.63
B29: ※ 산출면적 = 주문 판수 × 정척면적(현장식 산출서 '면적(M2)'). 합계는 산출서 '산출면적 계'와 같다. 판정은 두께별 행을 먼저 본다(두께가 다르면 다른 자재). 체적은 두께 차이 보정용 참고.

Sheet 04_종합요약
A2: ■ 단열재 실행 대비 현장 산출 수량 비교표
B4: (1) 실행 vs SW
B5: 구 분 | C5: 두께 | D5: 금액(원) | E5: 장 수 (매) | J5: SW산출면적 (㎡) | O5: 실제면적 (㎡) | Q5: 비 고
D6: 단가 | E6: 실행 수량(A) | F6: SW산출수량(B) | H6: 물량 차이(C=B-A) | J6: 실행 수량(A) | K6: SW산출수량(B) | M6: 물량 차이(C=B-A) | O6: SW 실제면적*10%(D)
F7: 수량 (B) | G7: 비율 (B/A) | H7: 수량 (C) | I7: 비율 (C/A) | K7: 수량 (B) | L7: 비율 (B/A) | M7: 수량 (C) | N7: 비율 (C/A) | O7: 수량 (D) | P7: 비율 (D/A)
B8: 남원주1차 | C8: =IF('03_현장별비교'!B17="","",'03_현장별비교'!B17&"T") -> 50T | D8: =4300/2 -> 2150 | E8: =N('03_현장별비교'!O17) -> 46062 | F8: =N('03_현장별비교'!Q17) -> 45025 | G8: =IF(E8=0,"-",F8/E8) -> 0.97748687 | H8: =F8-E8 -> -1037 | I8: =IF(E8=0,"-",H8/E8) -> -0.022513134 | J8: =N('03_현장별비교'!C17) -> 119761 | K8: =N('03_현장별비교'!E17) -> 117065 | L8: =IF(J8=0,"-",K8/J8) -> 0.9774885 | M8: =K8-J8 -> -2696 | N8: =IF(J8=0,"-",M8/J8) -> -0.022511502 | O8: =N('03_현장별비교'!K17)*1.1 -> 116741.03 | P8: - | Q8: =M8*D8 -> -5796400
C9: =IF('03_현장별비교'!B16="","",'03_현장별비교'!B16&"T") -> 90T | D9: 4300 | E9: =N('03_현장별비교'!O16) -> 21022 | F9: =N('03_현장별비교'!Q16) -> 20874 | G9: =IF(E9=0,"-",F9/E9) -> 0.99295976 | H9: =F9-E9 -> -148 | I9: =IF(E9=0,"-",H9/E9) -> -0.0070402436 | J9: =N('03_현장별비교'!C16) -> 54657 | K9: =N('03_현장별비교'!E16) -> 54272.4 | L9: =IF(J9=0,"-",K9/J9) -> 0.99296339 | M9: =K9-J9 -> -384.6 | N9: =IF(J9=0,"-",M9/J9) -> -0.0070366101 | O9: =N('03_현장별비교'!K16)*1.1 -> 55837.892 | Q9: =M9*D9 -> -1653780
C10: 소 계 | D10: - | E10: =SUM(E8:E9) -> 67084 | F10: =SUM(F8:F9) -> 65899 | G10: =IF(E10=0,"-",F10/E10) -> 0.98233558 | H10: =F10-E10 -> -1185 | I10: =IF(E10=0,"-",H10/E10) -> -0.017664421 | J10: =SUM(J8:J9) -> 174418 | K10: =SUM(K8:K9) -> 171337.4 | L10: =IF(J10=0,"-",K10/J10) -> 0.98233783 | M10: =K10-J10 -> -3080.6 | N10: =IF(J10=0,"-",M10/J10) -> -0.017662168 | O10: =SUM(O8:O9) -> 172578.92 | P10: =IF(OR(J10=0,O10=0),"-",O10/J10) -> 0.98945592 | Q10: =Q8+Q9 -> -7450180
B11: 부산장안 | C11: =IF('03_현장별비교'!B8="","",'03_현장별비교'!B8&"T") -> 55T | D11: 3080 | E11: =N('03_현장별비교'!O8) -> 20290 | F11: =N('03_현장별비교'!Q8) -> 19541 | G11: =IF(E11=0,"-",F11/E11) -> 0.96308526 | H11: =F11-E11 -> -749 | I11: =IF(E11=0,"-",H11/E11) -> -0.036914736 | J11: =N('03_현장별비교'!C8) -> 48210 | K11: =N('03_현장별비교'!E8) -> 46429.4 | L11: =IF(J11=0,"-",K11/J11) -> 0.96306575 | M11: =K11-J11 -> -1780.6 | N11: =IF(J11=0,"-",M11/J11) -> -0.036934246 | O11: =N('03_현장별비교'!K8)*1.1 -> 46366.463 | P11: - | Q11: =M11*D11 -> -5484248
C12: =IF('03_현장별비교'!B7="","",'03_현장별비교'!B7&"T") -> 95T | D12: 5320 | E12: =N('03_현장별비교'!O7) -> 10702 | F12: =N('03_현장별비교'!Q7) -> 11315 | G12: =IF(E12=0,"-",F12/E12) -> 1.057279 | H12: =F12-E12 -> 613 | I12: =IF(E12=0,"-",H12/E12) -> 0.057279013 | J12: =N('03_현장별비교'!C7) -> 25427 | K12: =N('03_현장별비교'!E7) -> 26884.4 | L12: =IF(J12=0,"-",K12/J12) -> 1.057317 | M12: =K12-J12 -> 1457.4 | N12: =IF(J12=0,"-",M12/J12) -> 0.057317025 | O12: =N('03_현장별비교'!K7)*1.1 -> 27802.896 | Q12: =M12*D12 -> 7753368
C13: 소 계 | D13: - | E13: =SUM(E11:E12) -> 30992 | F13: =SUM(F11:F12) -> 30856 | G13: =IF(E13=0,"-",F13/E13) -> 0.99561177 | H13: =F13-E13 -> -136 | I13: =IF(E13=0,"-",H13/E13) -> -0.0043882292 | J13: =SUM(J11:J12) -> 73637 | K13: =SUM(K11:K12) -> 73313.8 | L13: =IF(J13=0,"-",K13/J13) -> 0.9956109 | M13: =K13-J13 -> -323.2 | N13: =IF(J13=0,"-",M13/J13) -> -0.0043890979 | O13: =SUM(O11:O12) -> 74169.359 | P13: =IF(OR(J13=0,O13=0),"-",O13/J13) -> 1.0072295 | Q13: =Q11+Q12 -> 2269120
B14: 세종2차 | C14: =IF('03_현장별비교'!B26="","",'03_현장별비교'!B26&"T") -> 40T | D14: 2000 | E14: =N('03_현장별비교'!O26) -> 15880 | F14: =N('03_현장별비교'!Q26) -> 15327 | G14: =IF(E14=0,"-",F14/E14) -> 0.96517632 | H14: =F14-E14 -> -553 | I14: =IF(E14=0,"-",H14/E14) -> -0.034823678 | J14: =N('03_현장별비교'!C26) -> 42716 | K14: =N('03_현장별비교'!E26) -> 41229.63 | L14: =IF(J14=0,"-",K14/J14) -> 0.96520344 | M14: =K14-J14 -> -1486.37 | N14: =IF(J14=0,"-",M14/J14) -> -0.034796563 | O14: =N('03_현장별비교'!K26)*1.1 -> 38197.06 | P14: - | Q14: =M14*D14 -> -2972740
C15: =IF('03_현장별비교'!B25="","",'03_현장별비교'!B25&"T") -> 70T | D15: 3600 | E15: =N('03_현장별비교'!O25) -> 63545 | F15: =N('03_현장별비교'!Q25) -> 64697 | G15: =IF(E15=0,"-",F15/E15) -> 1.0181289 | H15: =F15-E15 -> 1152 | I15: =IF(E15=0,"-",H15/E15) -> 0.018128885 | J15: =N('03_현장별비교'!C25) -> 170936 | K15: =N('03_현장별비교'!E25) -> 174034.93 | L15: =IF(J15=0,"-",K15/J15) -> 1.0181292 | M15: =K15-J15 -> 3098.93 | N15: =IF(J15=0,"-",M15/J15) -> 0.018129183 | O15: =N('03_현장별비교'!K25)*1.1 -> 179999.7 | Q15: =M15*D15 -> 11156148
C16: 소 계 | D16: - | E16: =SUM(E14:E15) -> 79425 | F16: =SUM(F14:F15) -> 80024 | G16: =IF(E16=0,"-",F16/E16) -> 1.0075417 | H16: =F16-E16 -> 599 | I16: =IF(E16=0,"-",H16/E16) -> 0.007541706 | J16: =SUM(J14:J15) -> 213652 | K16: =SUM(K14:K15) -> 215264.56 | L16: =IF(J16=0,"-",K16/J16) -> 1.0075476 | M16: =K16-J16 -> 1612.56 | N16: =IF(J16=0,"-",M16/J16) -> 0.0075476008 | O16: =SUM(O14:O15) -> 218196.76 | P16: =IF(OR(J16=0,O16=0),"-",O16/J16) -> 1.0212718 | Q16: =Q14+Q15 -> 8183408
B17: 합 계 | D17: - | E17: =E10+E13+E16 -> 177501 | F17: =F10+F13+F16 -> 176779 | G17: =IF(E17=0,"-",F17/E17) -> 0.99593242 | H17: =F17-E17 -> -722 | I17: =IF(E17=0,"-",H17/E17) -> -0.0040675827 | J17: =J10+J13+J16 -> 461707 | K17: =K10+K13+K16 -> 459915.76 | L17: =IF(J17=0,"-",K17/J17) -> 0.9961204 | M17: =K17-J17 -> -1791.24 | N17: =IF(J17=0,"-",M17/J17) -> -0.0038796033 | O17: =O10+O13+O16 -> 464945.04 | P17: =IF(OR(J17=0,O17=0),"-",O17/J17) -> 1.0070132 | Q17: =Q16+Q13+Q10 -> 3002348
B20: (2) 현장산출 vs SW
B21: 구 분 | C21: 두께 | E21: 장 수 (매) | J21: 산출면적 (㎡) | O21: 실제면적 (㎡) | Q21: 비 고
E22: 현장산출 수량(A) | F22: SW산출수량(B) | H22: 물량 차이(C=B-A) | J22: 현장산출 수량(A) | K22: SW산출수량(B) | M22: 물량 차이(C=B-A) | O22: SW 실제면적*10%(D)
F23: 수량 (B) | G23: 비율 (B/A) | H23: 수량 (C) | I23: 비율 (C/A) | K23: 수량 (B) | L23: 비율 (B/A) | M23: 수량 (C) | N23: 비율 (C/A) | O23: 수량 (D) | P23: 비율 (D/A)
B24: 남원주1차 | C24: =IF('03_현장별비교'!B17="","",'03_현장별비교'!B17&"T") -> 50T | E24: =N('03_현장별비교'!P17) -> 43888 | F24: =N('03_현장별비교'!Q17) -> 45025 | G24: =IF(E24=0,"-",F24/E24) -> 1.0259069 | H24: =F24-E24 -> 1137 | I24: =IF(E24=0,"-",H24/E24) -> 0.025906854 | J24: =N('03_현장별비교'!D17) -> 114109 | K24: =N('03_현장별비교'!E17) -> 117065 | L24: =IF(J24=0,"-",K24/J24) -> 1.0259051 | M24: =K24-J24 -> 2956 | N24: =IF(J24=0,"-",M24/J24) -> 0.025905056 | O24: =N('03_현장별비교'!K17)*1.1 -> 116741.03 | P24: =IF(OR(J24=0,O24=0),"-",O24/J24) -> 1.0230659
C25: =IF('03_현장별비교'!B16="","",'03_현장별비교'!B16&"T") -> 90T | E25: =N('03_현장별비교'!P16) -> 21857 | F25: =N('03_현장별비교'!Q16) -> 20874 | G25: =IF(E25=0,"-",F25/E25) -> 0.95502585 | H25: =F25-E25 -> -983 | I25: =IF(E25=0,"-",H25/E25) -> -0.04497415 | J25: =N('03_현장별비교'!D16) -> 56829 | K25: =N('03_현장별비교'!E16) -> 54272.4 | L25: =IF(J25=0,"-",K25/J25) -> 0.95501241 | M25: =K25-J25 -> -2556.6 | N25: =IF(J25=0,"-",M25/J25) -> -0.044987594 | O25: =N('03_현장별비교'!K16)*1.1 -> 55837.892 | P25: =IF(OR(J25=0,O25=0),"-",O25/J25) -> 0.98255982
C26: 소 계 | E26: =SUM(E24:E25) -> 65745 | F26: =SUM(F24:F25) -> 65899 | G26: =IF(E26=0,"-",F26/E26) -> 1.0023424 | H26: =F26-E26 -> 154 | I26: =IF(E26=0,"-",H26/E26) -> 0.0023423835 | J26: =SUM(J24:J25) -> 170938 | K26: =SUM(K24:K25) -> 171337.4 | L26: =IF(J26=0,"-",K26/J26) -> 1.0023365 | M26: =K26-J26 -> 399.4 | N26: =IF(J26=0,"-",M26/J26) -> 0.0023365197 | O26: =SUM(O24:O25) -> 172578.92 | P26: =IF(OR(J26=0,O26=0),"-",O26/J26) -> 1.0095995
B27: 부산장안 | C27: =IF('03_현장별비교'!B8="","",'03_현장별비교'!B8&"T") -> 55T | E27: =N('03_현장별비교'!P8) -> 18200 | F27: =N('03_현장별비교'!Q8) -> 19541 | G27: =IF(E27=0,"-",F27/E27) -> 1.0736813 | H27: =F27-E27 -> 1341 | I27: =IF(E27=0,"-",H27/E27) -> 0.073681319 | J27: =N('03_현장별비교'!D8) -> 43244 | K27: =N('03_현장별비교'!E8) -> 46429.4 | L27: =IF(J27=0,"-",K27/J27) -> 1.0736611 | M27: =K27-J27 -> 3185.4 | N27: =IF(J27=0,"-",M27/J27) -> 0.073661086 | O27: =N('03_현장별비교'!K8)*1.1 -> 46366.463 | P27: =IF(OR(J27=0,O27=0),"-",O27/J27) -> 1.0722057
C28: =IF('03_현장별비교'!B7="","",'03_현장별비교'!B7&"T") -> 95T | E28: =N('03_현장별비교'!P7) -> 12467 | F28: =N('03_현장별비교'!Q7) -> 11315 | G28: =IF(E28=0,"-",F28/E28) -> 0.90759605 | H28: =F28-E28 -> -1152 | I28: =IF(E28=0,"-",H28/E28) -> -0.092403946 | J28: =N('03_현장별비교'!D7) -> 29621 | K28: =N('03_현장별비교'!E7) -> 26884.4 | L28: =IF(J28=0,"-",K28/J28) -> 0.90761284 | M28: =K28-J28 -> -2736.6 | N28: =IF(J28=0,"-",M28/J28) -> -0.092387158 | O28: =N('03_현장별비교'!K7)*1.1 -> 27802.896 | P28: =IF(OR(J28=0,O28=0),"-",O28/J28) -> 0.93862111
C29: 소 계 | E29: =SUM(E27:E28) -> 30667 | F29: =SUM(F27:F28) -> 30856 | G29: =IF(E29=0,"-",F29/E29) -> 1.006163 | H29: =F29-E29 -> 189 | I29: =IF(E29=0,"-",H29/E29) -> 0.0061629765 | J29: =SUM(J27:J28) -> 72865 | K29: =SUM(K27:K28) -> 73313.8 | L29: =IF(J29=0,"-",K29/J29) -> 1.0061593 | M29: =K29-J29 -> 448.8 | N29: =IF(J29=0,"-",M29/J29) -> 0.0061593358 | O29: =SUM(O27:O28) -> 74169.359 | P29: =IF(OR(J29=0,O29=0),"-",O29/J29) -> 1.017901
B30: 세종2차 | C30: =IF('03_현장별비교'!B26="","",'03_현장별비교'!B26&"T") -> 40T | E30: =N('03_현장별비교'!P26) -> 15880 | F30: =N('03_현장별비교'!Q26) -> 15327 | G30: =IF(E30=0,"-",F30/E30) -> 0.96517632 | H30: =F30-E30 -> -553 | I30: =IF(E30=0,"-",H30/E30) -> -0.034823678 | J30: =N('03_현장별비교'!D26) -> 42716 | K30: =N('03_현장별비교'!E26) -> 41229.63 | L30: =IF(J30=0,"-",K30/J30) -> 0.96520344 | M30: =K30-J30 -> -1486.37 | N30: =IF(J30=0,"-",M30/J30) -> -0.034796563 | O30: =N('03_현장별비교'!K26)*1.1 -> 38197.06 | P30: =IF(OR(J30=0,O30=0),"-",O30/J30) -> 0.89420966
C31: =IF('03_현장별비교'!B25="","",'03_현장별비교'!B25&"T") -> 70T | E31: =N('03_현장별비교'!P25) -> 63545 | F31: =N('03_현장별비교'!Q25) -> 64697 | G31: =IF(E31=0,"-",F31/E31) -> 1.0181289 | H31: =F31-E31 -> 1152 | I31: =IF(E31=0,"-",H31/E31) -> 0.018128885 | J31: =N('03_현장별비교'!D25) -> 170936 | K31: =N('03_현장별비교'!E25) -> 174034.93 | L31: =IF(J31=0,"-",K31/J31) -> 1.0181292 | M31: =K31-J31 -> 3098.93 | N31: =IF(J31=0,"-",M31/J31) -> 0.018129183 | O31: =N('03_현장별비교'!K25)*1.1 -> 179999.7 | P31: =IF(OR(J31=0,O31=0),"-",O31/J31) -> 1.0530239
C32: 소 계 | E32: =SUM(E30:E31) -> 79425 | F32: =SUM(F30:F31) -> 80024 | G32: =IF(E32=0,"-",F32/E32) -> 1.0075417 | H32: =F32-E32 -> 599 | I32: =IF(E32=0,"-",H32/E32) -> 0.007541706 | J32: =SUM(J30:J31) -> 213652 | K32: =SUM(K30:K31) -> 215264.56 | L32: =IF(J32=0,"-",K32/J32) -> 1.0075476 | M32: =K32-J32 -> 1612.56 | N32: =IF(J32=0,"-",M32/J32) -> 0.0075476008 | O32: =SUM(O30:O31) -> 218196.76 | P32: =IF(OR(J32=0,O32=0),"-",O32/J32) -> 1.0212718
B33: 합 계 | E33: =E26+E29+E32 -> 175837 | F33: =F26+F29+F32 -> 176779 | G33: =IF(E33=0,"-",F33/E33) -> 1.0053572 | H33: =F33-E33 -> 942 | I33: =IF(E33=0,"-",H33/E33) -> 0.0053572343 | J33: =J26+J29+J32 -> 457455 | K33: =K26+K29+K32 -> 459915.76 | L33: =IF(J33=0,"-",K33/J33) -> 1.0053792 | M33: =K33-J33 -> 2460.76 | N33: =IF(J33=0,"-",M33/J33) -> 0.0053792395 | O33: =O26+O29+O32 -> 464945.04 | P33: =IF(OR(J33=0,O33=0),"-",O33/J33) -> 1.0163733
B35: (3) 현장별 적용 두께 · 판 규격
B37: 구 분 | C37: 지역 | E37: 직접외기 (1P+2P) | G37: 간접외기 (1P+2P) | I37: 판 규격 (가로×세로) | K37: 비교 범위 | M37: 플랫폼 REV
B38: 남원주1차 | C38: ='01_현장조건'!C$4 -> 중부1 | E38: ='01_현장조건'!C$13&"T + "&'01_현장조건'!C$14&"T" -> 90T + 50T | G38: ='01_현장조건'!C$16&"T + "&'01_현장조건'!C$17&"T" -> 50T + 50T | I38: =TEXT('01_현장조건'!C$10,"#,##0")&" × "&TEXT('01_현장조건'!C$11,"#,##0")&" ("&TEXT('01_현장조건'!C$12,"0.000")&"㎡)" -> 1,000 × 2,600 (2.600㎡) | K38: ='01_현장조건'!C$6 -> 전체 900세대 | M38: ='01_현장조건'!C$7 -> 84A타입(401동~404동) · REV 35
B39: 부산장안 | C39: ='01_현장조건'!B$4 -> 남부 | E39: ='01_현장조건'!B$13&"T + "&'01_현장조건'!B$14&"T" -> 95T + 55T | G39: ='01_현장조건'!B$16&"T + "&'01_현장조건'!B$17&"T" -> 55T + 55T | I39: =TEXT('01_현장조건'!B$10,"#,##0")&" × "&TEXT('01_현장조건'!B$11,"#,##0")&" ("&TEXT('01_현장조건'!B$12,"0.000")&"㎡)" -> 900 × 2,640 (2.376㎡) | K39: ='01_현장조건'!B$6 -> 전체 419세대 | M39: ='01_현장조건'!B$7 -> 부산장안 단열재 산출_rev2 · REV 7
B40: 세종2차 | C40: ='01_현장조건'!D$4 -> 중부2 | E40: ='01_현장조건'!D$13&"T + "&'01_현장조건'!D$14&"T" -> 70T + 70T | G40: ='01_현장조건'!D$16&"T + "&'01_현장조건'!D$17&"T" -> 70T + 40T | I40: =TEXT('01_현장조건'!D$10,"#,##0")&" × "&TEXT('01_현장조건'!D$11,"#,##0")&" ("&TEXT('01_현장조건'!D$12,"0.000")&"㎡)" -> 1,000 × 2,690 (2.690㎡) | K40: ='01_현장조건'!D$6 -> 전체 1,110세대 (59 320 + 84 790) | M40: ='01_현장조건'!D$7 -> 세종2차임대 · REV 19(59) + REV 18(84)
B42: ※ 장수 = 산출면적 ÷ 현장별 판 면적(반올림). 실행·현장산출 장수도 같은 판 규격으로 환산한 값 — 현장 발주 규격이 다르면 실제 장수와 차이 날 수 있다.
B43: ※ 판 규격이 현장마다 달라(부산 900×2640 · 남원주 1000×2600 · 세종 1000×2690) 3개 현장 장수 합계는 참고용이다. 현장 간 총량 비교는 산출면적(㎡) 기준.
B44: ※ 비율(B/A)·차이(C)는 같은 현장·같은 두께끼리 계산. 소계·합계는 두께 합산. (2) 비고 판정은 산출면적 오차율 · 01_현장조건 하단 허용치 기준.
B45: ※ 두께별 상세·로스율은 03_현장별비교, 지표 요약·그래프는 04-1_지표요약(참고).
B46: ※ SW 실제면적×10%(D) = 플랫폼(SW) 실면적(전개면 − 창호, 나누기 전) × 1.1. 비율(D/A)은 각 표의 A(실행 / 현장산출 산출면적) 대비.

Sheet 04-1_지표요약(참고)
A1: 04. 종합 요약 — 3개 현장
A2: 보고용 1페이지. 비교 기준 = 산출면적(㎡). 두께가 다른 현장끼리는 로스율(산출÷실면적−1)로 비교. 자동 계산.
B4: 현장 | C4: 지역 | D4: 두께 구성 (1P+2P) | E4: 실면적 (㎡, 참고) | F4: 산출면적 ㎡ (비교 기준) | I4: 로스율 | L4: 플랫폼 정확도 | N4: 실행 대비 증감률
F5: 실행기준 | G5: 현장산출 | H5: 플랫폼 | I5: 실행기준 | J5: 현장산출 | K5: 플랫폼 | L5: 오차율 (vs 현장) | M5: 판정 | N5: 현장산출 | O5: 플랫폼
B6: ='01_현장조건'!B$3 -> 부산장안 | C6: =IF('01_현장조건'!B$4="","",'01_현장조건'!B$4) -> 남부 | D6: =IF(AND('01_현장조건'!B$13="",'01_현장조건'!B$16=""),"두께 미입력","직접 "&'01_현장조건'!B$13&"+"&'01_현장조건'!B$14&"T / 간접 "&'01_현장조건'!B$16&"+"&'01_현장조건'!B$17&"T") -> 직접 95+55T / 간접 55+55T | E6: ='03_현장별비교'!K10 -> 67426.69 | F6: ='03_현장별비교'!C10 -> 73637 | G6: ='03_현장별비교'!D10 -> 72865 | H6: ='03_현장별비교'!E10 -> 73313.8 | I6: ='03_현장별비교'!L10 -> 0.092104625 | J6: ='03_현장별비교'!M10 -> 0.080655153 | K6: ='03_현장별비교'!N10 -> 0.087311271 | L6: ='03_현장별비교'!G10 -> 0.0061593358 | M6: ='03_현장별비교'!H10 -> 적합 | N6: =IF(OR(F6="",G6="",F6=0),"",G6/F6-1) -> -0.01048386 | O6: =IF(OR(F6="",H6="",F6=0),"",H6/F6-1) -> -0.0043890979
B7: ='01_현장조건'!C$3 -> 남원주1차 | C7: =IF('01_현장조건'!C$4="","",'01_현장조건'!C$4) -> 중부1 | D7: =IF(AND('01_현장조건'!C$13="",'01_현장조건'!C$16=""),"두께 미입력","직접 "&'01_현장조건'!C$13&"+"&'01_현장조건'!C$14&"T / 간접 "&'01_현장조건'!C$16&"+"&'01_현장조건'!C$17&"T") -> 직접 90+50T / 간접 50+50T | E7: ='03_현장별비교'!K19 -> 156889.93 | F7: ='03_현장별비교'!C19 -> 174418 | G7: ='03_현장별비교'!D19 -> 170938 | H7: ='03_현장별비교'!E19 -> 171337.4 | I7: ='03_현장별비교'!L19 -> 0.11172208 | J7: ='03_현장별비교'!M19 -> 0.089540928 | K7: ='03_현장별비교'!N19 -> 0.092086662 | L7: ='03_현장별비교'!G19 -> 0.0023365197 | M7: ='03_현장별비교'!H19 -> 적합 | N7: =IF(OR(F7="",G7="",F7=0),"",G7/F7-1) -> -0.019952069 | O7: =IF(OR(F7="",H7="",F7=0),"",H7/F7-1) -> -0.017662168
B8: ='01_현장조건'!D$3 -> 세종2차 | C8: =IF('01_현장조건'!D$4="","",'01_현장조건'!D$4) -> 중부2 | D8: =IF(AND('01_현장조건'!D$13="",'01_현장조건'!D$16=""),"두께 미입력","직접 "&'01_현장조건'!D$13&"+"&'01_현장조건'!D$14&"T / 간접 "&'01_현장조건'!D$16&"+"&'01_현장조건'!D$17&"T") -> 직접 70+70T / 간접 70+40T | E8: ='03_현장별비교'!K28 -> 198360.69 | F8: ='03_현장별비교'!C28 -> 213652 | G8: ='03_현장별비교'!D28 -> 213652 | H8: ='03_현장별비교'!E28 -> 215264.56 | I8: ='03_현장별비교'!L28 -> 0.077088409 | J8: ='03_현장별비교'!M28 -> 0.077088409 | K8: ='03_현장별비교'!N28 -> 0.085217842 | L8: ='03_현장별비교'!G28 -> 0.0075476008 | M8: ='03_현장별비교'!H28 -> 적합 | N8: =IF(OR(F8="",G8="",F8=0),"",G8/F8-1) -> 0 | O8: =IF(OR(F8="",H8="",F8=0),"",H8/F8-1) -> 0.0075476008
B9: 3개 현장 계 | E9: =IF(COUNT(E6:E8)=0,"",SUM(E6:E8)) -> 422677.31 | F9: =IF(COUNT(F6:F8)=0,"",SUM(F6:F8)) -> 461707 | G9: =IF(COUNT(G6:G8)=0,"",SUM(G6:G8)) -> 457455 | H9: =IF(COUNT(H6:H8)=0,"",SUM(H6:H8)) -> 459915.76 | I9: =IF(OR(F9="",E9="",E9=0),"",F9/E9-1) -> 0.092339213 | J9: =IF(OR(G9="",E9="",E9=0),"",G9/E9-1) -> 0.082279529 | K9: =IF(OR(H9="",E9="",E9=0),"",H9/E9-1) -> 0.08810137 | L9: =IF(OR(G9="",H9="",G9=0),"",H9/G9-1) -> 0.0053792395 | M9: =IF(L9="","",IF(ABS(L9)<='01_현장조건'!$B$31,"적합",IF(ABS(L9)<='01_현장조건'!$B$32,"검토","부적합"))) -> 적합 | N9: =IF(OR(F9="",G9="",F9=0),"",G9/F9-1) -> -0.0092093037 | O9: =IF(OR(F9="",H9="",F9=0),"",H9/F9-1) -> -0.0038796033
B10: ※ 산출면적 = 주문 판수 × 정척면적. 오차율·판정 허용치는 01_현장조건 하단. 실행 대비 증감률이 음수면 실행보다 적게 주문(절감). 두께별 상세는 03 시트.
B12: 종합 의견 (작성)
B13: 정확도 | C13: 예) 3개 현장 모두 플랫폼 산출면적이 현장 산출과 ±3% 이내(적합) — 두께별 최대 편차 ○㎡
B14: 절감 효과
B15: 두께 영향 | C15: 예) 지역별 두께가 달라도 로스율은 ○~○% 로 비슷 → 두께와 무관하게 배치 로직이 일관됨
B16: 개선 과제

Sheet 05_차이원인
A1: 05. 차이 원인 분석
A2: 플랫폼 ↔ 현장 차이가 난 두께·겹마다 한 줄. 원인 분류·조치 구분은 목록에서 선택.
A4: No | B4: 현장 | C4: 두께(T) | D4: 겹 | E4: 차이(㎡) 플랫폼−현장 | F4: 원인 분류 | G4: 상세 설명 (근거) | H4: 조치 구분 | I4: 조치 내용 | J4: 상태
A5: 1 | B5: 남원주1차 | C5: 50 | D5: 2P | F5: 2P 시작 위치 | G5: [참고 — 84C 기준층 개발 검증, 이번 합계 비교와 범위 다름] 현장 도면은 2P 이음매를 1P와 50~90mm만 비켜 면마다 온장으로 시작. 플랫폼 물량 최소 모드는 면별 시작 위치 탐색 적용 후 2P 42판(현장 44판). 적용 전에는 49판(커밋 823176e·21bc46f). | H5: 정상 편차 | I5: 현장산출 입력 후 이 경향이 현장 전체에서도 나오는지 확인 | J5: 확인 필요
A6: 2
A7: 3
A8: 4
A9: 5
A10: 6
A11: 7
A12: 8
A13: 9
A14: 10
A15: 11
A16: 12
A17: 13
... A29: 25
B31: ※ 1번 행은 개발 검증 기록(84C 기준층 도면 복원 모델)의 참고 사례. 현장산출을 채운 뒤 실제 차이로 다시 적을 것.

Sheet 06_검증조건
A1: 06. 비교 전제 조건 체크리스트
A2: 세 값(실행기준·현장산출·플랫폼산출)이 같은 조건에서 나왔는지 먼저 확인. 미확인 항목이 있으면 그 현장 판정은 보류.
A4: No | B4: 확인 항목 | C4: 확인 방법 | D4: ='01_현장조건'!B3 -> 부산장안 | E4: ='01_현장조건'!C3 -> 남원주1차 | F4: ='01_현장조건'!D3 -> 세종2차
A5: 1 | B5: 같은 도면(REV) 사용 | C5: 플랫폼 프로젝트 REV 와 현장 나누기도의 원본 도면 파일·날짜 대조 | D5: 미확인 | E5: 미확인 | F5: 미확인
A6: 2 | B6: 비교 범위(동·타입·층) 일치 | C6: 실행 수량이 동 전체면 플랫폼·현장도 같은 범위로 환산(02 반복수) | D6: 미확인 | E6: 미확인 | F6: 미확인
A7: 3 | B7: 보드 규격 일치 | C7: 현장 발주 규격(예 1000×600)과 플랫폼 보드 L×H 동일 | D7: 미확인 | E7: 미확인 | F7: 미확인
A8: 4 | B8: 노출 구분(직접/간접외기) 지정 일치 | C8: 플랫폼 입면 변별 노출타입이 현장 설계도서와 같은지 | D8: 미확인 | E8: 미확인 | F8: 미확인
A9: 5 | B9: 두께(1P/2P) 설계 일치 | C9: 01 시트 두께 = 단열 상세도/특기시방 두께 | D9: 미확인 | E9: 미확인 | F9: 미확인
A10: 6 | B10: 창호·개구부 반영 일치 | C10: 플랫폼 오프닝 위치·치수가 창호도와 일치, 누락 없음 | D10: 미확인 | E10: 미확인 | F10: 미확인
A11: 7 | B11: 코너 랩(엇갈림) 방식 일치 | C11: 외부 모서리에서 어느 겹이 감싸는지 현장 방식과 같은지 | D11: 미확인 | E11: 미확인 | F11: 미확인
A12: 8 | B12: 버림 기준·자투리 재사용 기준 일치 | C12: 플랫폼 버림 기준 폭과 현장 재사용 관행 | D12: 미확인 | E12: 미확인 | F12: 미확인
A13: 9 | B13: 현장산출 출처 명확 | C13: 나누기도 / 발주서 / 실투입 중 무엇인지 02 시트 '자료 출처'에 기록 | D13: 미확인 | E13: 미확인 | F13: 미확인
A14: 10 | B14: 실행기준 출처 명확 | C14: 실행예산서 항목·할증률 기록, 대체 산정이면 비고 표기 | D14: 미확인 | E14: 미확인 | F14: 미확인
A15: 11 | B15: 플랫폼 산출 모드 기록 | C15: 물량 최소 / 시공성 우선 — 01 시트 | D15: 미확인 | E15: 미확인 | F15: 미확인
A16: 12 | B16: 수량 단위 통일 | C16: 모두 산출면적(㎡ = 주문 판수 × 정척면적)으로 맞춤 — 실면적·조각 면적과 혼동 금지 | D16: 미확인 | E16: 미확인 | F16: 미확인
B17: 확인 완료율 | D17: =IFERROR((COUNTIF(D5:D16,"확인")+COUNTIF(D5:D16,"해당없음"))/ROWS(D5:D16),"") -> 0 | E17: =IFERROR((COUNTIF(E5:E16,"확인")+COUNTIF(E5:E16,"해당없음"))/ROWS(E5:E16),"") -> 0 | F17: =IFERROR((COUNTIF(F5:F16,"확인")+COUNTIF(F5:F16,"해당없음"))/ROWS(F5:F16),"") -> 0
B18: 판정 가능 여부 | D18: =IF(COUNTIF(D5:D16,"불일치")>0,"조건 불일치",IF(D17=1,"판정 가능","보류")) -> 보류 | E18: =IF(COUNTIF(E5:E16,"불일치")>0,"조건 불일치",IF(E17=1,"판정 가능","보류")) -> 보류 | F18: =IF(COUNTIF(F5:F16,"불일치")>0,"조건 불일치",IF(F17=1,"판정 가능","보류")) -> 보류

Sheet 07_플랫폼원자료
A1: 07. 플랫폼 원자료 — 현장식 산출서 동별 집계표
A2: 스마트덱 최신 REV(DB elev_revisions)를 현재 배포 코드(origin/main 86e1fa2)로 계산해 받은 '현장식 산출서 CSV' 원본. 2026-09-30 추출. 수정 금지.
A4: 부산장안 — '부산장안 단열재 산출_rev2' REV 7 (2026-09-28) ★비교 사용
A5: 판 면적 2.376㎡ — 판수 = 면적 ÷ 판 면적. 면적(M2) = 주문 판수 × 정척면적, 실면적 = 전개면 − 오프닝.
A6: 동 | B6: 단위세대 타입 | C6: 1~3F | D6: 지붕층 | E6: 기준층 | F6: 세대수 | G6: 층고(1~3F/지붕/기준) | H6: 55T 면적(M2) | I6: 95T 면적(M2) | J6: 55T 실면적(M2) | K6: 95T 실면적(M2) | L6: 55T 로스율(%) | M6: 95T 로스율(%) | N6: 실면적 계(M2) | O6: 산출면적 계(M2) | P6: 차이(M2) | Q6: 로스율(%)
A7: 101동 | B7: 59A(기준측) | C7: 0 | D7: 1 | E7: 0 | F7: 1 | G7: 2840/2840/2640 | H7: 114 | I7: 71.3 | J7: 107.62 | K7: 68.16 | L7: 6 | M7: 4.6 | N7: 175.78 | O7: 185.33 | P7: 9.55 | Q7: 5.4
A8: 101동 | B8: 59A(변형) | C8: 0 | D8: 0 | E8: 22 | F8: 22 | G8: 2840/2840/2640 | H8: 2770.4 | I8: 1777.2 | J8: 2582.74 | K8: 1772.49 | L8: 7.3 | M8: 0.3 | N8: 4355.22 | O8: 4547.66 | P8: 192.44 | Q8: 4.4
A9: 101동 | B9: 59B(기준) | C9: 0 | D9: 1 | E9: 23 | F9: 24 | G9: 2840/2840/2640 | H9: 3031.8 | I9: 1316.3 | J9: 2834.94 | K9: 1264.57 | L9: 6.9 | M9: 4.1 | N9: 4099.51 | O9: 4348.08 | P9: 248.57 | Q9: 6.1
A10: 101동 | B10: 84A(기준측) | C10: 1 | D10: 1 | E10: 22 | F10: 24 | G10: 2840/2840/2640 | H10: 2865.5 | I10: 1777.2 | J10: 2610.84 | K10: 1728.34 | L10: 9.8 | M10: 2.8 | N10: 4339.18 | O10: 4642.7 | P10: 303.53 | Q10: 7
A11: 101동 | B11: 84A(기준) | C11: 2 | D11: 2 | E11: 44 | F11: 48 | G11: 2840/2840/2640 | H11: 4704.5 | I11: 2528.1 | J11: 4213.38 | K11: 2424.16 | L11: 11.7 | M11: 4.3 | N11: 6637.54 | O11: 7232.54 | P11: 595 | Q11: 9
A12: 102동 | B12: 59A(기준) | C12: 0 | D12: 1 | E12: 20 | F12: 21 | G12: 2840/2840/2640 | H12: 1950.7 | I12: 1052.6 | J12: 1743.38 | K12: 965.38 | L12: 11.9 | M12: 9 | N12: 2708.76 | O12: 3003.26 | P12: 294.5 | Q12: 10.9
A13: 102동 | B13: 59A(변형) | C13: 1 | D13: 1 | E13: 22 | F13: 24 | G13: 2840/2840/2640 | H13: 3036.5 | I13: 1953.1 | J13: 2837.51 | K13: 1947.39 | L13: 7 | M13: 0.3 | N13: 4784.89 | O13: 4989.6 | P13: 204.71 | Q13: 4.3
A14: 102동 | B14: 59B(기준) | C14: 1 | D14: 0 | E14: 21 | F14: 22 | G14: 2840/2840/2640 | H14: 2779.9 | I14: 1207 | J14: 2599.52 | K14: 1159.57 | L14: 6.9 | M14: 4.1 | N14: 3759.08 | O14: 3986.93 | P14: 227.84 | Q14: 6.1
A15: 102동 | B15: 59B(변형) | C15: 0 | D15: 2 | E15: 0 | F15: 2 | G15: 2840/2840/2640 | H15: 308.9 | I15: 156.8 | J15: 294.52 | K15: 151.53 | L15: 4.9 | M15: 3.5 | N15: 446.05 | O15: 465.7 | P15: 19.65 | Q15: 4.4
A16: 102동 | B16: 84A(기준측) | C16: 1 | D16: 1 | E16: 20 | F16: 22 | G16: 2840/2840/2640 | H16: 2627.9 | I16: 1629.9 | J16: 2394.84 | K16: 1585.36 | L16: 9.7 | M16: 2.8 | N16: 3980.21 | O16: 4257.79 | P16: 277.59 | Q16: 7
A17: 102동 | B17: 84A(기준) | C17: 1 | D17: 1 | E17: 20 | F17: 22 | G17: 2840/2840/2640 | H17: 2157.4 | I17: 1159.5 | J17: 1932.44 | K17: 1111.86 | L17: 11.6 | M17: 4.3 | N17: 3044.3 | O17: 3316.9 | P17: 272.6 | Q17: 9
A18: 103동 | B18: 59A(기준측) | C18: 1 | D18: 1 | E18: 23 | F18: 25 | G18: 2840/2840/2640 | H18: 2687.3 | I18: 1618.1 | J18: 2480.01 | K18: 1563.87 | L18: 8.4 | M18: 3.5 | N18: 4043.88 | O18: 4305.31 | P18: 261.43 | Q18: 6.5
